Workbook

Sheet All
A1: CQ | B1: Prompt | C1: Claude_Result | D1: Claude_Raw | E1: sparql_query | F1: eval_json | G1: syntax_ok | H1: satisfiable | I1: deterministic | J1: rows | K1: vars | L1: latency_p50_ms | M1: latency_p95_ms | N1: latency_mean_ms | O1: lexical_query_overlap | P1: semantic_similarity_to_CQ | Q1: semantic_soft_coverage_to_CQ | R1: tuple_cohesion | S1: always_unbound_vars | T1: variables | U1: difficulty | V1: determinism_score | W1: satisfiability_binding_score | X1: h1_overall | Y1: semantic_diversity_score
A2: Who are all the characters available? | B2: Task: Write a SPARQL query that answers the following competency question: Who are all the characters available? Requirements: - Use the schema to determine correct URIs and relationships. - Ensure the query retrieves the necessary information efficiently. - Provide only one full SPARQL query without placeholders. - Don't summarize or return an analysis of the given schema but return only the respective SPARQL query for the Competency Question. Context: Below is the TTL schema of the knowledge graph: @prefix dc: <http://purl.org/dc/elements/1.1/> . @prefix dcterms: <http://purl.org/dc/terms/> . @prefix foaf: <http://xmlns.com/foaf/0.1/> . @prefix ns1: <http://dbkwik.webdatacommons.org/marvelcinematicuniverse.wikia.com/property/> . @prefix ns2: <http://dbkwik.webdatacommons.org/marvelcinematicuniverse.wikia.com/property/affiliation(s)> . @prefix ns3: <http://dbkwik.webdatacommons.org/ontology/> . @prefix ns6: <http://dbkwik.webdatacommons.org/marvelcinematicuniverse.wikia.com/property/%23> . @prefix owl: <http://www.w3.org/2002/07/owl#> . @prefix rdf: <http://www.w3.org/1999/02/22-rdf-syntax-ns#> . @prefix rdfs: <http://www.w3.org/2000/01/rdf-schema#> . @prefix skos: <http://www.w3.org/2004/02/skos/core#> . @prefix xsd: <http://www.w3.org/2001/XMLSchema#> . <http://dbkwik.webdatacommons.org/marvelcinematicuniverse.wikia.com/> a owl:Ontology . ns6: a rdf:Property ; rdfs:label "#"@en . ns1:actor a rdf:Property ; rdfs:label "actor"@en . ns1:affiliation a rdf:Property ; rdfs:label "affiliation"@en . ns2: a rdf:Property ; rdfs:label "affiliation(s)"@en . ns1:after a rdf:Property ; rdfs:label "After"@en . ns1:age a rdf:Property ; rdfs:label "age"@en . ns1:alias a rdf:Property ; rdfs:label "alias"@en . ns1:allies a rdf:Property ; rdfs:label "allies"@en . ns1:appearances a rdf:Property ; rdfs:label "appearances"@en . ns1:artista a rdf:Property ; rdfs:label "artista"@en . ns1:artists a rdf:Property ; rdfs:label "artists"@en . ns1:author a rdf:Property ; rdfs:label "author"@en . ns1:battles a rdf:Property ; rdfs:label "battles"@en . ns1:before a rdf:Property ; rdfs:label "Before"@en . ns1:begin a rdf:Property ; rdfs:label "begin"@en . ns1:body a rdf:Property ; rdfs:label "body"@en . ns1:boxoffice a rdf:Property ; rdfs:label "boxoffice"@en . ns1:builder a rdf:Property ; rdfs:label "builder"@en . ns1:casualties a rdf:Property ; rdfs:label "casualties"@en . ns1:channel a rdf:Property ; rdfs:label "channel"@en . ns1:charaacter a rdf:Property ; rdfs:label "charaacter"@en . ns1:character a rdf:Property ; rdfs:label "character"@en . ns1:citizenship a rdf:Property ; rdfs:label "citizenship"@en . ns1:clearance a rdf:Property ; rdfs:label "clearance"@en . ns1:coat a rdf:Property ; rdfs:label "coat"@en . ns1:combatants a rdf:Property ; rdfs:label "combatants"@en . ns1:comic a rdf:Property ; rdfs:label "comic"@en . ns1:commanders a rdf:Property ; rdfs:label "commanders"@en . ns1:composer a rdf:Property ; rdfs:label "composer"@en . ns1:conc a rdf:Property ; rdfs:label "conc"@en . ns1:continent a rdf:Property ; rdfs:label "continent"@en . ns1:contribution a rdf:Property ; rdfs:label "contribution"@en . ns1:contributors a rdf:Property ; rdfs:label "contributors"@en . ns1:cover a rdf:Property ; rdfs:label "cover"@en . ns1:creator a rdf:Property ; rdfs:label "creator"@en . ns1:current a rdf:Property ; rdfs:label "Current"@en . ns1:date a rdf:Property ; rdfs:label "date"@en . ns1:dates a rdf:Property ; rdfs:label "dates"@en . ns1:defender a rdf:Property ; rdfs:label "defender"@en . ns1:developers a rdf:Property ; rdfs:label "developers"@en . ns1:directed a rdf:Property ; rdfs:label "directed"@en . ns1:director a rdf:Property ; rdfs:label "director"@en . ns1:directors a rdf:Property ; rdfs:label "directors"@en . ns1:dob a rdf:Property ; rdfs:label "DOB"@en . ns1:documentary a rdf:Property ; rdfs:label "documentary"@en . ns1:dod a rdf:Property ; rdfs:label "DOD"@en . ns1:duration a rdf:Property ; rdfs:label "duration"@en . ns1:eason a rdf:Property ; rdfs:label "eason"@en . ns1:editorinchief a rdf:Property ; rdfs:label "editorinchief"@en . ns1:end a rdf:Property ; rdfs:label "end"@en . ns1:episodes a rdf:Property ; rdfs:label "episodes"@en . ns1:executor a rdf:Property ; rdfs:label "executor"@en . ns1:film a rdf:Property ; rdfs:label "film"@en . ns1:films a rdf:Property ; rdfs:label "films"@en . ns1:first a rdf:Property ; rdfs:label "first"@en . ns1:firstAired a rdf:Property ; rdfs:label "first aired"@en . ns1:flag a rdf:Property ; rdfs:label "flag"@en . ns1:followedBy a rdf:Property ; rdfs:label "followed by"@en . ns1:formerLeader a rdf:Property ; rdfs:label "former leader"@en . ns1:formerinhabitants a rdf:Property ; rdfs:label "formerinhabitants"@en . ns1:formerleaders a rdf:Property ; rdfs:label "formerleaders"@en . ns1:formermembers a rdf:Property ; rdfs:label "formermembers"@en . ns1:formernotable a rdf:Property ; rdfs:label "formernotable"@en . ns1:founder a rdf:Property ; rdfs:label "founder"@en . ns1:game a rdf:Property ; rdfs:label "game"@en . ns1:gender a rdf:Property ; rdfs:label "gender"@en . ns1:heading a rdf:Property ; rdfs:label "heading"@en . ns1:headquarters a rdf:Property ; rdfs:label "headquarters"@en . ns1:height a rdf:Property ; rdfs:label "height"@en . ns1:homeplanet a rdf:Property ; rdfs:label "homeplanet"@en . ns1:idno a rdf:Property ; rdfs:label "IDno"@en . ns1:imagebg a rdf:Property ; rdfs:label "imageBG"@en . ns1:imagecaption a rdf:Property ; rdfs:label "imagecaption"@en . ns1:inhabitants a rdf:Property ; rdfs:label "inhabitants"@en . ns1:interest a rdf:Property ; rdfs:label "interest"@en . ns1:isbn a rdf:Property ; rdfs:label "isbn"@en . ns1:last a rdf:Property ; rdfs:label "last"@en . ns1:leader a rdf:Property ; rdfs:label "leader"@en . ns1:link a rdf:Property ; rdfs:label "link"@en . ns1:location a rdf:Property ; rdfs:label "location"@en . ns1:locations a rdf:Property ; rdfs:label "locations"@en . ns1:made a rdf:Property ; rdfs:label "made"@en . ns1:media a rdf:Property ; rdfs:label "media"@en . ns1:members a rdf:Property ; rdfs:label "members"@en . ns1:movie a rdf:Property ; rdfs:label "movie"@en . ns1:movies a rdf:Property ; rdfs:label "movies"@en . ns1:name a rdf:Property ; rdfs:label "name"@en . ns1:namesake a rdf:Property ; rdfs:label "namesake"@en . ns1:next a rdf:Property ; rdfs:label "next"@en . ns1:nonlinktext a rdf:Property ; rdfs:label "nonlinktext"@en . ns1:notable a rdf:Property ; rdfs:label "notable"@en . ns1:notableformer a rdf:Property ; rdfs:label "notableformer"@en . ns1:oneShot a rdf:Property ; rdfs:label "one-shot"@en . ns1:oneshot a rdf:Property ; rdfs:label "oneshot"@en . ns1:otherNames a rdf:Property ; rdfs:label "other names"@en . ns1:owner a rdf:Property ; rdfs:label "owner"@en . ns1:owners a rdf:Property ; rdfs:label "owners"@en . ns1:pages a rdf:Property ; rdfs:label "pages"@en . ns1:participants a rdf:Property ; rdfs:label "participants"@en . ns1:passengers a rdf:Property ; rdfs:label "passengers"@en . ns1:penciled a rdf:Property ; rdfs:label "penciled"@en . ns1:performer a rdf:Property ; rdfs:label "performer"@en . ns1:pilot a rdf:Property ; rdfs:label "pilot"@en . ns1:place a rdf:Property ; rdfs:label "place"@en . ns1:planet a rdf:Property ; rdfs:label "planet"@en . ns1:planner a rdf:Property ; rdfs:label "planner"@en . ns1:population a rdf:Property ; rdfs:label "population"@en . ns1:precededBy a rdf:Property ; rdfs:label "preceded by"@en . ns1:prev a rdf:Property ; rdfs:label "prev"@en . ns1:previous a rdf:Property ; rdfs:label "previous"@en . ns1:prisoners a rdf:Property ; rdfs:label "prisoners"@en . ns1:produced a rdf:Property ; rdfs:label "produced"@en . ns1:producer a rdf:Property ; rdfs:label "producer"@en . ns1:publisher a rdf:Property ; rdfs:label "publisher"@en . ns1:realName a rdf:Property ; rdfs:label "real name"@en . ns1:release a rdf:Property ; rdfs:label "release"@en . ns1:released a rdf:Property ; rdfs:label "released"@en . ns1:result a rdf:Property ; rdfs:label "result"@en . ns1:runntime a rdf:Property ; rdfs:label "runntime"@en . ns1:runtime a rdf:Property ; rdfs:label "runtime"@en . ns1:seal a rdf:Property ; rdfs:label "seal"@en . ns1:season a rdf:Property ; rdfs:label "season"@en . ns1:series a rdf:Property ; rdfs:label "series"@en . ns1:showrunners a rdf:Property ; rdfs:label "showrunners"@en . ns1:side a rdf:Property ; rdfs:label "side"@en . ns1:species a rdf:Property ; rdfs:label "species"@en . ns1:srclink a rdf:Property ; rdfs:label "srclink"@en . ns1:status a rdf:Property ; rdfs:label "status"@en . ns1:succeeded a rdf:Property ; rdfs:label "succeeded"@en . ns1:succeededBy a rdf:Property ; rdfs:label "succeeded by"@en . ns1:system a rdf:Property ; rdfs:label "system"@en . ns1:target a rdf:Property ; rdfs:label "target"@en . ns1:team a rdf:Property ; rdfs:label "team"@en . ns1:text a rdf:Property ; rdfs:label "text"@en . ns1:title a rdf:Property ; rdfs:label "title"@en . ns1:tvSeries a rdf:Property ; rdfs:label "tv series"@en . ns1:type a rdf:Property ; rdfs:label "type"@en . ns1:users a rdf:Property ; rdfs:label "users"@en . ns1:vehicles a rdf:Property ; rdfs:label "vehicles"@en . ns1:voiceActor a rdf:Property ; rdfs:label "voice actor"@en . ns1:war a rdf:Property ; rdfs:label "war"@en . ns1:weapons a rdf:Property ; rdfs:label "weapons"@en . ns1:webSeries a rdf:Property ; rdfs:label "web series"@en . ns1:writer a rdf:Property ; rdfs:label "writer"@en . ns1:writers a rdf:Property ; rdfs:label "writers"@en . ns1:wrote a rdf:Property ; rdfs:label "wrote"@en . ns1:years a rdf:Property ; rdfs:label "years"@en . <http://dbkwik.webdatacommons.org/marvelcinematicuniverse.wikia.com/resource/%5BAKA_Start_at_the_Beginning> ns3:wikiPageWikiLinkText "[AKA Start at the Beginning"^^rdf:langString . <http://dbkwik.webdatacommons.org/marvelcinematicuniverse.wikia.com/resource/%5BVladimir_Ranskahov> ns3:wikiPageWikiLinkText "Ranskahov"^^rdf:langString . <http://dbkwik.webdatacommons.org/marvelcinematicuniverse.wikia.com/resource/...And_Finally:_Black_Bolt/Gallery> a owl:Thing ; rdfs:label "...And Finally: Black Bolt/Gallery"^^rdf:langString ; ns3:abstract """A gallery of images of, or related to, the Inhumans episode ...And Finally: Black Bolt. """@en ; ns3:thumbnail <http://marvelcinematicuniverse.wikia.com/wiki/Special:FilePath/...And_Finally_Black_Bolt_photo.jpg?width=300>, <http://marvelcinematicuniverse.wikia.com/wiki/Special:FilePath/And_Finally_Black_Bolt_1.jpg?width=300> ; ns3:wikiPageWikiLink <http://dbkwik.webdatacommons.org/marvelcinematicuniverse.wikia.com/resource/...And_Finally:_Black_Bolt>, <http://dbkwik.webdatacommons.org/marvelcinematicuniverse.wikia.com/resource/Category:Galleries> ; dcterms:subject <http://dbkwik.webdatacommons.org/marvelcinematicuniverse.wikia.com/resource/Category:Galleries> ; rdfs:comment """A gallery of images of, or related to, the Inhumans episode ...And Finally: Black Bolt. """@en ; skos:altLabel "...And Finally: Black Bolt/Gallery"^^rdf:langString ; foaf:depiction <http://marvelcinematicuniverse.wikia.com/wiki/Special:FilePath/...And_Finally_Black_Bolt_photo.jpg>, <http://marvelcinematicuniverse.wikia.com/wiki/Special:FilePath/And_Finally_Black_Bolt_1.jpg> . <http://dbkwik.webdatacommons.org/marvelcinematicuniverse.wikia.com/resource/.380> a <http://dbkwik.webdatacommons.org/marvelcinematicuniverse.wikia.com/class/episode> ; rdfs:label ".380"^^rdf:langString ; ns1:director <http://dbkwik.webdatacommons.org/marvelcinematicuniverse.wikia.com/resource/Stephen_Surjik> ; ns1:firstAired "2016-03-18"^^xsd:date ; ns1:next <http://dbkwik.webdatacommons.org/marvelcinematicuniverse.wikia.com/resource/The_Dark_at_the_End_of_the_Tunnel> ; ns1:previous <http://dbkwik.webdatacommons.org/marvelcinematicuniverse.wikia.com/resource/The_Man_in_the_Box> ; ns1:season 2 ; ns1:writer <http://dbkwik.webdatacommons.org/marvelcinematicuniverse.wikia.com/resource/Mark_Verheiden> ; ns3:abstract """.380 is the eleventh episode of the second season of the Netflix exclusive television series Daredevil. """@en ; ns3:thumbnail <http://marvelcinematicuniverse.wikia.com/wiki/Special:FilePath/BMahoneyQuestioningKPage-S2E11.jpg?width=300>, <http://marvelcinematicuniverse.wikia.com/wiki/Special:FilePath/Daredevil-Episode-211-3-03212016.jpg?width=300> ; ns3:wikiPageExternalLink <http://marvel.wikia.com/wiki/Main_Page> ; ns3:wikiPageWikiLink <http://dbkwik.webdatacommons.org/marvelcinematicuniverse.wikia.com/resource/15th_Precinct_Police_Station> ; dcterms:subject <http://dbkwik.webdatacommons.org/marvelcinematicuniverse.wikia.com/resource/Category:Daredevil_(TV_series)_Episodes> ; rdfs:comment """.380 is the eleventh episode of the second season of the Netflix exclusive television series Daredevil. """@en ; skos:altLabel ".380"^^rdf:langString ; foaf:depiction <http://marvelcinematicuniverse.wikia.com/wiki/Special:FilePath/0-8-4_episode.png> . <http://dbkwik.webdatacommons.org/marvelcinematicuniverse.wikia.com/resource/.380/Gallery> a owl:Thing ; rdfs:label ".380/Gallery"^^rdf:langString ; ns3:abstract """A gallery of images from, or related to, the Daredevil episode .380. """@en ; dcterms:subject <http://dbkwik.webdatacommons.org/marvelcinematicuniverse.wikia.com/resource/Category:Daredevil_(TV_series)>, <http://dbkwik.webdatacommons.org/marvelcinematicuniverse.wikia.com/resource/Category:Galleries> ; rdfs:comment """A gallery of images from, or related to, the Daredevil episode .380. """@en ; skos:altLabel ".380/Gallery"^^rdf:langString . <http://dbkwik.webdatacommons.org/marvelcinematicuniverse.wikia.com/resource/0-8-4_(disambiguation)> a <http://dbkwik.webdatacommons.org/marvelcinematicuniverse.wikia.com/class/disambig> ; rdfs:label "0-8-4 (disambiguation)"^^rdf:langString ; ns3:wikiPageDisambiguates <http://dbkwik.webdatacommons.org/marvelcinematicuniverse.wikia.com/resource/0-8-4_(Code)>, <http://dbkwik.webdatacommons.org/marvelcinematicuniverse.wikia.com/resource/0-8-4_(episode)> . <http://dbkwik.webdatacommons.org/marvelcinematicuniverse.wikia.com/resource/0-8-4_(episode)/Gallery> a owl:Thing ; rdfs:label "0-8-4 (episode)/Gallery"^^rdf:langString ; rdfs:comment """A gallery of images from, or related to, the Agents of S.H.I.E.L.D. episode 0-8-4. """@en . <http://dbkwik.webdatacommons.org/marvelcinematicuniverse.wikia.com/resource/107th_Infantry_Regiment> a <http://dbkwik.webdatacommons.org/marvelcinematicuniverse.wikia.com/class/organization> ; rdfs:label "107th Infantry Regiment"^^rdf:langString ; ns1:formermembers <http://dbkwik.webdatacommons.org/marvelcinematicuniverse.wikia.com/resource/Joseph_Rogers>, <http://dbkwik.webdatacommons.org/marvelcinematicuniverse.wikia.com/resource/Winter_Soldier> ; ns1:headquarters <http://dbkwik.webdatacommons.org/marvelcinematicuniverse.wikia.com/resource/New_York> ; ns1:leader <http://dbkwik.webdatacommons.org/marvelcinematicuniverse.wikia.com/resource/Chester_Phillips> ; ns1:locations <http://dbkwik.webdatacommons.org/marvelcinematicuniverse.wikia.com/resource/Europe>, <http://dbkwik.webdatacommons.org/marvelcinematicuniverse.wikia.com/resource/United_States_of_America> ; ns1:members <http://dbkwik.webdatacommons.org/marvelcinematicuniverse.wikia.com/resource/Gilmore_Hodge> ; ns1:movie <http://dbkwik.webdatacommons.org/marvelcinematicuniverse.wikia.com/resource/Captain_America:_The_First_Avenger> ; ns1:tvSeries <http://dbkwik.webdatacommons.org/marvelcinematicuniverse.wikia.com/resource/Agent_Carter_(TV_series)>, <http://dbkwik.webdatacommons.org/marvelcinematicuniverse.wikia.com/resource/The_Iron_Ceiling> ; rdfs:comment """The 107th Infantry Regiment was a regiment of the New York Army National Guard. They fought for the United States Army for periods of time throughout the Twentieth Century, most notably during the Great War and World War II. They served with distinction, being instrumental in the destruction of Nazi Germany and the HYDRA threat. """@en . <http://dbkwik.webdatacommons.org/marvelcinematicuniverse.wikia.com/resource/10cc> a <http://dbkwik.webdatacommons.org/marvelcinematicuniverse.wikia.com/class/music> ; rdfs:label "10cc"^^rdf:langString ; ns3:wikiPageExternalLink <http://play.spotify.com>, <https://play.spotify.com/artist/6i6WlGzQtXtz7GcC5H5st5/> ; rdfs:comment """10cc are an English art rock band. Their song "I'm Not in Love" is featured in Guardians of the Galaxy. """@en . <http://dbkwik.webdatacommons.org/marvelcinematicuniverse.wikia.com/resource/10th_Precinct_Police_Station> a <http://dbkwik.webdatacommons.org/marvelcinematicuniverse.wikia.com/class/location> ; rdfs:label "10th Precinct Police Station"^^rdf:langString ; ns1:continent <http://dbkwik.webdatacommons.org/marvelcinematicuniverse.wikia.com/resource/North_America> ; ns1:location <http://dbkwik.webdatacommons.org/marvelcinematicuniverse.wikia.com/resource/New_York>, <http://dbkwik.webdatacommons.org/marvelcinematicuniverse.wikia.com/resource/New_York_City> ; ns1:tvSeries <http://dbkwik.webdatacommons.org/marvelcinematicuniverse.wikia.com/resource/Front_Toward_Enemy>, <http://dbkwik.webdatacommons.org/marvelcinematicuniverse.wikia.com/resource/The_Punisher> ; rdfs:comment """The 10th Precinct Police Station is one of the police stations based in New York City. """@en . <http://dbkwik.webdatacommons.org/marvelcinematicuniverse.wikia.com/resource/1900s> a <http://dbkwik.webdatacommons.org/marvelcinematicuniverse.wikia.com/class/timeline> ; rdfs:label "1900s"^^rdf:langString ; ns1:before <http://dbkwik.webdatacommons.org/marvelcinematicuniverse.wikia.com/resource/Before_20th_Century> ; rdfs:comment """This is a timeline of events that occurred during the 1900s. """@en . <http://dbkwik.webdatacommons.org/marvelcinematicuniverse.wikia.com/resource/1910s> a <http://dbkwik.webdatacommons.org/marvelcinematicuniverse.wikia.com/class/timeline> ; rdfs:label "1910s"^^rdf:langString ; rdfs:comment """This is a timeline of events that occurred during the 1910s. """@en . <http://dbkwik.webdatacommons.org/marvelcinematicuniverse.wikia.com/resource/1920s> a <http://dbkwik.webdatacommons.org/marvelcinematicuniverse.wikia.com/class/timeline> ; rdfs:label "1920s"^^rdf:langString ; rdfs:comment """This is a timeline of events that occurred during the 1920s. """@en . <http://dbkwik.webdatacommons.org/marvelcinematicuniverse.wikia.com/resource/1930s> a <http://dbkwik.webdatacommons.org/marvelcinematicuniverse.wikia.com/class/timeline> ; rdfs:label "1930s"^^rdf:langString ; rdfs:comment """This is a timeline of events that occurred during the 1930s. """@en . <http://dbkwik.webdatacommons.org/marvelcinematicuniverse.wikia.com/resource/1960s> a <http://dbkwik.webdatacommons.org/marvelcinematicuniverse.wikia.com/class/timeline> ; rdfs:label "1960s"^^rdf:langString ; rdfs:comment """This is a timeline of events that occurred during the 1960s. """@en . <http://dbkwik.webdatacommons.org/marvelcinematicuniverse.wikia.com/resource/1970s> a <http://dbkwik.webdatacommons.org/marvelcinematicuniverse.wikia.com/class/timeline> ; rdfs:label "1970s"^^rdf:langString ; rdfs:comment """This is a timeline of events that occurred during the 1970s. """@en . <http://dbkwik.webdatacommons.org/marvelcinematicuniverse.wikia.com/resource/2018> rdfs:label "2018"^^rdf:langString ; ns1:after <http://dbkwik.webdatacommons.org/marvelcinematicuniverse.wikia.com/resource/2091> ; rdfs:comment """This is a timeline of events that occurred during 2018. """@en . <http://dbkwik.webdatacommons.org/marvelcinematicuniverse.wikia.com/resource/21_the_Producer> a <http://dbkwik.webdatacommons.org/marvelcinematicuniverse.wikia.com/class/music> ; rdfs:label "21 the Producer"^^rdf:langString ; rdfs:comment """21 the Producer is a musician and songwriter. His collaboration with Xzibit, Demrick and Sylvester Jordan Jr., "Finders Keepers", is featured in Captain America: Civil War. His song "Missionary" is featured in the Luke Cage episode Moment of Truth. """@en . <http://dbkwik.webdatacommons.org/marvelcinematicuniverse.wikia.com/resource/29th_Precinct_Police_Station> a <http://dbkwik.webdatacommons.org/marvelcinematicuniverse.wikia.com/class/location> ; rdfs:label "29th Precinct Police Station"^^rdf:langString ; ns1:continent <http://dbkwik.webdatacommons.org/marvelcinematicuniverse.wikia.com/resource/North_America> ; ns1:location <http://dbkwik.webdatacommons.org/marvelcinematicuniverse.wikia.com/resource/New_York>, <http://dbkwik.webdatacommons.org/marvelcinematicuniverse.wikia.com/resource/New_York_City> ; rdfs:comment """The 29th Precinct Police Station is one of the major police stations based in Harlem, New York City. """@en . <http://dbkwik.webdatacommons.org/marvelcinematicuniverse.wikia.com/resource/2_Chainz> a <http://dbkwik.webdatacommons.org/marvelcinematicuniverse.wikia.com/class/music> ; rdfs:label "2 Chainz"^^rdf:langString ; rdfs:comment """Tauheed Epps, known professionally as 2 Chainz, is an American rapper. His collaboration with ScHoolboy Q and Saudi, "X", is featured on Black Panther: The Album. """@en . <http://dbkwik.webdatacommons.org/marvelcinematicuniverse.wikia.com/resource/3OH!3> a <http://dbkwik.webdatacommons.org/marvelcinematicuniverse.wikia.com/class/music> ; rdfs:label "3OH!3"^^rdf:langString ; rdfs:comment """3OH!3 are an American electropop duo. Their song "Bad Guy" is featured on Iron Man 3: Heroes Fall – Music Inspired by the Motion Picture, an album with music inspired by (but not used in) Iron Man 3. """@en . <http://dbkwik.webdatacommons.org/marvelcinematicuniverse.wikia.com/resource/3_AM> a <http://dbkwik.webdatacommons.org/marvelcinematicuniverse.wikia.com/class/episode> ; rdfs:label "3 AM"^^rdf:langString ; ns1:director <http://dbkwik.webdatacommons.org/marvelcinematicuniverse.wikia.com/resource/Tom_Shankland> ; ns1:firstAired "2017-11-17"^^xsd:date ; ns1:next <http://dbkwik.webdatacommons.org/marvelcinematicuniverse.wikia.com/resource/Two_Dead_Men> ; ns1:season 1 ; rdfs:comment """3 AM is the first episode of the first season of the television series The Punisher. """@en . <http://dbkwik.webdatacommons.org/marvelcinematicuniverse.wikia.com/resource/3_AM/Gallery> a owl:Thing ; rdfs:label "3 AM/Gallery"^^rdf:langString ; rdfs:comment """A gallery of images from, or related to, the The Punisher episode 3 AM. """@en . <http://dbkwik.webdatacommons.org/marvelcinematicuniverse.wikia.com/resource/4,722_Hours> a <http://dbkwik.webdatacommons.org/marvelcinematicuniverse.wikia.com/class/episode> ; rdfs:label "4,722 Hours"^^rdf:langString ; ns1:director <http://dbkwik.webdatacommons.org/marvelcinematicuniverse.wikia.com/resource/Jesse_Bochco> ; ns1:firstAired "2015-10-27"^^xsd:date ; ns1:next <http://dbkwik.webdatacommons.org/marvelcinematicuniverse.wikia.com/resource/Among_Us_Hide...> ; ns1:previous <http://dbkwik.webdatacommons.org/marvelcinematicuniverse.wikia.com/resource/Devils_You_Know> ; ns1:season 3 ; rdfs:comment """4,722 Hours is the fifth episode of the third season of the television series Agents of S.H.I.E.L.D. and the forty-ninth episode overall. """@en . <http://dbkwik.webdatacommons.org/marvelcinematicuniverse.wikia.com/resource/4,722_Hours/Gallery> a owl:Thing ; rdfs:label "4,722 Hours/Gallery"^^rdf:langString ; rdfs:comment """A gallery of images from, or related to, the Agents of S.H.I.E.L.D. episode 4,722 Hours. """@en . <http://dbkwik.webdatacommons.org/marvelcinematicuniverse.wikia.com/resource/7kingZ> a <http://dbkwik.webdatacommons.org/marvelcinematicuniverse.wikia.com/class/music> ; rdfs:label "7kingZ"^^rdf:langString ; rdfs:comment """7kingZ are an American hip hop group. Their song "Born For This" is featured in the Cloak & Dagger episode Princeton Offense. """@en . <http://dbkwik.webdatacommons.org/marvelcinematicuniverse.wikia.com/resource/A$AP_Ferg> a <http://dbkwik.webdatacommons.org/marvelcinematicuniverse.wikia.com/class/wps> ; rdfs:label "A$AP Ferg"^^rdf:langString ; rdfs:comment """Darold Ferguson, Jr., professionally known as A$AP Ferg, is an American rapper. His collaboration with Remy Ma, "East Coast", is featured in the Runaways episode Kingdom. He contributed to the soundtrack of Luke Cage. """@en . <http://dbkwik.webdatacommons.org/marvelcinematicuniverse.wikia.com/resource/A%27Lars> a <http://dbkwik.webdatacommons.org/marvelcinematicuniverse.wikia.com/class/character> ; rdfs:label "A'Lars"^^rdf:langString ; ns1:citizenship <http://dbkwik.webdatacommons.org/marvelcinematicuniverse.wikia.com/resource/Titan> ; ns1:gender "Male"^^rdf:langString ; ns1:movie <http://dbkwik.webdatacommons.org/marvelcinematicuniverse.wikia.com/resource/Avengers:_Infinity_War> ; ns1:species <http://dbkwik.webdatacommons.org/marvelcinematicuniverse.wikia.com/resource/Titans> ; rdfs:comment """A'Lars was a Titan and the father of the galactic warlord Thanos. """@en . <http://dbkwik.webdatacommons.org/marvelcinematicuniverse.wikia.com/resource/A.I.M._Arc_Armiger> a <http://dbkwik.webdatacommons.org/marvelcinematicuniverse.wikia.com/class/item> ; rdfs:label "A.I.M. Arc Armiger"^^rdf:langString ; ns1:creator <http://dbkwik.webdatacommons.org/marvelcinematicuniverse.wikia.com/resource/A.I.M.> ; ns1:game <http://dbkwik.webdatacommons.org/marvelcinematicuniverse.wikia.com/resource/Iron_Man_2_(video_game)> ; ns1:owners <http://dbkwik.webdatacommons.org/marvelcinematicuniverse.wikia.com/resource/A.I.M.> ; ns1:users <http://dbkwik.webdatacommons.org/marvelcinematicuniverse.wikia.com/resource/A.I.M.>, <http://dbkwik.webdatacommons.org/marvelcinematicuniverse.wikia.com/resource/Iron_Man> ; rdfs:comment """The A.I.M. Arc Armiger was an enhanced version of the Roxxon Armiger created with implants from Project P.R.O.T.E.A.N.. """@en . <http://dbkwik.webdatacommons.org/marvelcinematicuniverse.wikia.com/resource/A.I.M._Drones> a <http://dbkwik.webdatacommons.org/marvelcinematicuniverse.wikia.com/class/item> ; rdfs:label "A.I.M. Drones"^^rdf:langString ; ns1:creator <http://dbkwik.webdatacommons.org/marvelcinematicuniverse.wikia.com/resource/A.I.M.> ; ns1:game <http://dbkwik.webdatacommons.org/marvelcinematicuniverse.wikia.com/resource/Iron_Man_2_(video_game)> ; ns1:owners <http://dbkwik.webdatacommons.org/marvelcinematicuniverse.wikia.com/resource/A.I.M.> ; ns1:users <http://dbkwik.webdatacommons.org/marvelcinematicuniverse.wikia.com/resource/A.I.M.> ; rdfs:comment """A.I.M. Drones were were robotic military drones designed by A.I.M. """@en . <http://dbkwik.webdatacommons.org/marvelcinematicuniverse.wikia.com/resource/A.I.M._Gunship> a <http://dbkwik.webdatacommons.org/marvelcinematicuniverse.wikia.com/class/vehicle> ; rdfs:label "A.I.M. Gunship"^^rdf:langString ; ns1:builder <http://dbkwik.webdatacommons.org/marvelcinematicuniverse.wikia.com/resource/A.I.M.> ; ns1:game <http://dbkwik.webdatacommons.org/marvelcinematicuniverse.wikia.com/resource/Iron_Man_2_(video_game)> ; ns1:owner <http://dbkwik.webdatacommons.org/marvelcinematicuniverse.wikia.com/resource/A.I.M.> ; ns1:passengers <http://dbkwik.webdatacommons.org/marvelcinematicuniverse.wikia.com/resource/Iron_Man>, <http://dbkwik.webdatacommons.org/marvelcinematicuniverse.wikia.com/resource/War_Machine> ; ns1:users <http://dbkwik.webdatacommons.org/marvelcinematicuniverse.wikia.com/resource/A.I.M.>, <http://dbkwik.webdatacommons.org/marvelcinematicuniverse.wikia.com/resource/Black_Widow> ; rdfs:comment """A.I.M. Gunships were transport and combat vehicles developed by A.I.M.. """@en . <http://dbkwik.webdatacommons.org/marvelcinematicuniverse.wikia.com/resource/A.I.M._President> a <http://dbkwik.webdatacommons.org/marvelcinematicuniverse.wikia.com/class/character> ; rdfs:label "A.I.M. President"^^rdf:langString ; ns1:gender "Male"^^rdf:langString ; ns1:species <http://dbkwik.webdatacommons.org/marvelcinematicuniverse.wikia.com/resource/Humans> ; ns1:voiceActor <http://dbkwik.webdatacommons.org/marvelcinematicuniverse.wikia.com/resource/Fred_Tatasciore> ; rdfs:comment """The A.I.M. President was the CEO of Advanced Idea Mechanics. """@en . <http://dbkwik.webdatacommons.org/marvelcinematicuniverse.wikia.com/resource/A.J._Franklin> a <http://dbkwik.webdatacommons.org/marvelcinematicuniverse.wikia.com/class/actor> ; rdfs:label "A.J. Franklin"^^rdf:langString ; rdfs:comment """A.J. Franklin portrayed Protester #4 in the Luke Cage episodes Take It Personal and Now You're Mine. """@en . <http://dbkwik.webdatacommons.org/marvelcinematicuniverse.wikia.com/resource/A.R.M.O.R.> a <http://dbkwik.webdatacommons.org/marvelcinematicuniverse.wikia.com/class/organization> ; rdfs:label "A.R.M.O.R."^^rdf:langString ; ns1:locations <http://dbkwik.webdatacommons.org/marvelcinematicuniverse.wikia.com/resource/Hub_(S.H.I.E.L.D._Facility)> ; rdfs:comment """A.R.M.O.R. is an organization that had an office at the Hub. """@en . <http://dbkwik.webdatacommons.org/marvelcinematicuniverse.wikia.com/resource/A._Todd_Holland> a <http://dbkwik.webdatacommons.org/marvelcinematicuniverse.wikia.com/class/wps> ; rdfs:label "A. Todd Holland"^^rdf:langString ; rdfs:comment """A. Todd Holland was an art director on Thor. """@en . <http://dbkwik.webdatacommons.org/marvelcinematicuniverse.wikia.com/resource/AC/DC> a <http://dbkwik.webdatacommons.org/marvelcinematicuniverse.wikia.com/class/wps> ; rdfs:label "AC/DC"^^rdf:langString ; rdfs:comment """AC/DC are an Australian rock band. Their songs "Back in Black" and "Shoot to Thrill" are featured in Iron Man and The Avengers, respectively. The entire soundtrack of Iron Man 2 consists of AC/DC songs. """@en . <http://dbkwik.webdatacommons.org/marvelcinematicuniverse.wikia.com/resource/AKA_1,000_Cuts> rdfs:label "AKA 1,000 Cuts"^^rdf:langString ; ns1:next <http://dbkwik.webdatacommons.org/marvelcinematicuniverse.wikia.com/resource/AKA_I%27ve_Got_the_Blues> ; ns1:previous <http://dbkwik.webdatacommons.org/marvelcinematicuniverse.wikia.com/resource/AKA_Sin_Bin> ; rdfs:comment """AKA 1,000 Cuts is the tenth episode of the first season of the Netflix exclusive television series Jessica Jones. """@en . <http://dbkwik.webdatacommons.org/marvelcinematicuniverse.wikia.com/resource/A_Film_by_Peter_Parker> a <http://dbkwik.webdatacommons.org/marvelcinematicuniverse.wikia.com/class/item> ; rdfs:label "A Film by Peter Parker"^^rdf:langString ; ns1:creator <http://dbkwik.webdatacommons.org/marvelcinematicuniverse.wikia.com/resource/Spider-Man> ; ns1:owners <http://dbkwik.webdatacommons.org/marvelcinematicuniverse.wikia.com/resource/Spider-Man> ; rdfs:comment """A Film by Peter Parker is a recorded video diary of Peter Parker's trip to Berlin. """@en . <http://dbkwik.webdatacommons.org/marvelcinematicuniverse.wikia.com/resource/A_Flock_of_Seagulls> a <http://dbkwik.webdatacommons.org/marvelcinematicuniverse.wikia.com/class/wps> ; rdfs:label "A Flock of Seagulls"^^rdf:langString ; rdfs:comment """A Flock of Seagulls are an English new wave and synthpop band. Their song "Space Age Love Song" is featured in Spider-Man: Homecoming. """@en . <http://dbkwik.webdatacommons.org/marvelcinematicuniverse.wikia.com/resource/A_Tribe_Called_Quest> a <http://dbkwik.webdatacommons.org/marvelcinematicuniverse.wikia.com/class/wps> ; rdfs:label "A Tribe Called Quest"^^rdf:langString ; rdfs:comment """A Tribe Called Quest are an American hip-hop group. Their song "Award Tour" is featured in the Iron Fist episode Snow Gives Way. """@en . <http://dbkwik.webdatacommons.org/marvelcinem | C2: PREFIX rdfs: <http://www.w3.org/2000/01/rdf-schema#> SELECT DISTINCT ?character ?label WHERE { ?character a <http://dbkwik.webdatacommons.org/marvelcinematicuniverse.wikia.com/class/character> . OPTIONAL { ?character rdfs:label ?label . } } ORDER BY ?label ?character | D2: { "id": "batch_req_691fabe90ff08190a9aa3db791ac30ea", "custom_id": "cq-0", "response": { "status_code": 200, "request_id": "e3d558ca7b8e68806a454c91aae430be", "body": { "id": "chatcmpl-Ce8YXOjgMrlyo27FfJL68AER9ALEz", "object": "chat.completion", "created": 1763682045, "model": "gpt-5-2025-08-07", "choices": [ { "index": 0, "message": { "role": "assistant", "content": "PREFIX rdfs: <http://www.w3.org/2000/01/rdf-schema#>\nSELECT DISTINCT ?character ?label\nWHERE {\n ?character a <http://dbkwik.webdatacommons.org/marvelcinematicuniverse.wikia.com/class/character> .\n OPTIONAL { ?character rdfs:label ?label . }\n}\nORDER BY ?label ?character", "refusal": null, "annotations": [] }, "finish_reason": "stop" } ], "usage": { "prompt_tokens": 109317, "completion_tokens": 1369, "total_tokens": 110686, "prompt_tokens_details": { "cached_tokens": 0, "audio_tokens": 0 }, "completion_tokens_details": { "reasoning_tokens": 1280, "audio_tokens": 0, "accepted_prediction_tokens": 0, "rejected_prediction_tokens": 0 } }, "service_tier": "default", "system_fingerprint": null } }, "error": null } | E2: PREFIX dc: <http://purl.org/dc/elements/1.1/> PREFIX dcterms: <http://purl.org/dc/terms/> PREFIX foaf: <http://xmlns.com/foaf/0.1/> PREFIX ns1: <http://dbkwik.webdatacommons.org/marvelcinematicuniverse.wikia.com/property/> PREFIX ns2: <http://dbkwik.webdatacommons.org/marvelcinematicuniverse.wikia.com/property/affiliation(s)> PREFIX ns3: <http://dbkwik.webdatacommons.org/ontology/> PREFIX ns6: <http://dbkwik.webdatacommons.org/marvelcinematicuniverse.wikia.com/property/%23> PREFIX owl: <http://www.w3.org/2002/07/owl#> PREFIX rdf: <http://www.w3.org/1999/02/22-rdf-syntax-ns#> PREFIX skos: <http://www.w3.org/2004/02/skos/core#> PREFIX xsd: <http://www.w3.org/2001/XMLSchema#> PREFIX rdfs: <http://www.w3.org/2000/01/rdf-schema#> SELECT DISTINCT ?character ?label WHERE { ?character a <http://dbkwik.webdatacommons.org/marvelcinematicuniverse.wikia.com/class/character> . OPTIONAL { ?character rdfs:label ?label . } } ORDER BY ?label ?character | F2: { "cq_text": "Who are all the characters available?", "syntax_ok": true, "satisfiable": true, "deterministic": true, "latency": { "p50_ms": 104.74, "p95_ms": 105.14, "mean_ms": 104.67 }, "rows": 2262, "vars": 2, "always_unbound_vars": [], "lexical_query_overlap": 0.0, "semantic_similarity_to_CQ": 0.65, "semantic_soft_coverage_to_CQ": 0.72, "tuple_cohesion": 0.61, "variables": [ { "var": "character", "rows": 2262, "distinct": 1859, "null_rate": 0.0, "label_resolution_rate": 1.0, "diversity_entropy_norm": 0.98, "semantic_cohesion": 0.64, "dup_ratio": 0.18, "bound_rate": 1.0 }, { "var": "label", "rows": 2262, "distinct": 2262, "null_rate": 0.0, "label_resolution_rate": 1.0, "diversity_entropy_norm": 1.0, "semantic_cohesion": 0.65, "dup_ratio": 0.0, "bound_rate": 1.0 } ] } | G2: TRUE | H2: TRUE | I2: TRUE | J2: 2262 | K2: 2 | L2: 104.74 | M2: 105.14 | N2: 104.67 | O2: 0 | P2: 0.65 | Q2: 0.72 | R2: 0.61 | S2: [] | T2: [{"var": "character", "rows": 2262, "distinct": 1859, "null_rate": 0.0, "label_resolution_rate": 1.0, "diversity_entropy_norm": 0.98, "semantic_cohesion": 0.64, "dup_ratio": 0.18, "bound_rate": 1.0}, {"var": "label", "rows": 2262, "distinct": 2262, "null_rate": 0.0, "label_resolution_rate": 1.0, "diversity_entropy_norm": 1.0, "semantic_cohesion": 0.65, "dup_ratio": 0.0, "bound_rate": 1.0}] | U2: simple | V2: 1 | W2: 1 | X2: 1 | Y2: 0.75166667
