Workbook

Sheet Filter
A1: Complexity | B1: Total | C1: Valid Syntax | D1: Valid all
A2: {=_xlfn.UNIQUE(All!U2:U34)} | B2: =COUNTIF(All!U2:U34,Filter!A2) | C2: =COUNTIFS(All!$G:$G, TRUE, All!$U:$U, A2) | D2: =COUNTIFS(All!$G:$G, TRUE, All!$H:$H, TRUE, All!$I:$I, TRUE, All!$U:$U, A2)
A3: moderate | B3: =COUNTIF(All!U3:U35,Filter!A3) | C3: =COUNTIFS(All!$G:$G, TRUE, All!$U:$U, A3) | D3: =COUNTIFS(All!$G:$G, TRUE, All!$H:$H, TRUE, All!$I:$I, TRUE, All!$U:$U, A3)
A4: complex | B4: =COUNTIF(All!U4:U36,Filter!A4) | C4: =COUNTIFS(All!$G:$G, TRUE, All!$U:$U, A4) | D4: =COUNTIFS(All!$G:$G, TRUE, All!$H:$H, TRUE, All!$I:$I, TRUE, All!$U:$U, A4)

Sheet By-CQ-Level
A1: difficulty | B1: rows | C1: vars | D1: latency_p50_ms | E1: latency_p95_ms | F1: latency_mean_ms | G1: lexical_query_overlap | H1: semantic_similarity_to_CQ | I1: semantic_soft_coverage_to_CQ | J1: tuple_cohesion | K1: determinism_score | L1: satisfiability_binding_score | M1: h1_overall | N1: semantic_diversity_score | O1: syntax_ok_rate | P1: satisfiable_rate | Q1: deterministic_rate
A2: simple | B2: =AVERAGEIFS(All!$J:$J, All!$G:$G, TRUE, All!$H:$H, TRUE, All!$I:$I, TRUE, All!$U:$U, A2) | C2: =AVERAGEIFS(All!K:K, All!$G:$G, TRUE, All!$H:$H, TRUE, All!$I:$I, TRUE, All!$U:$U, $A2) | D2: =AVERAGEIFS(All!L:L, All!$G:$G, TRUE, All!$H:$H, TRUE, All!$I:$I, TRUE, All!$U:$U, $A2) | E2: =AVERAGEIFS(All!M:M, All!$G:$G, TRUE, All!$H:$H, TRUE, All!$I:$I, TRUE, All!$U:$U, $A2) | F2: =AVERAGEIFS(All!N:N, All!$G:$G, TRUE, All!$H:$H, TRUE, All!$I:$I, TRUE, All!$U:$U, $A2) | G2: =AVERAGEIFS(All!O:O, All!$G:$G, TRUE, All!$H:$H, TRUE, All!$I:$I, TRUE, All!$U:$U, $A2) | H2: =AVERAGEIFS(All!P:P, All!$G:$G, TRUE, All!$H:$H, TRUE, All!$I:$I, TRUE, All!$U:$U, $A2) | I2: =AVERAGEIFS(All!Q:Q, All!$G:$G, TRUE, All!$H:$H, TRUE, All!$I:$I, TRUE, All!$U:$U, $A2) | J2: =AVERAGEIFS(All!R:R, All!$G:$G, TRUE, All!$H:$H, TRUE, All!$I:$I, TRUE, All!$U:$U, $A2) | K2: =AVERAGEIFS(All!V:V, All!$G:$G, TRUE, All!$H:$H, TRUE, All!$I:$I, TRUE, All!$U:$U, $A2) | L2: =AVERAGEIFS(All!W:W, All!$G:$G, TRUE, All!$H:$H, TRUE, All!$I:$I, TRUE, All!$U:$U, $A2) | M2: =AVERAGEIFS(All!X:X, All!$G:$G, TRUE, All!$H:$H, TRUE, All!$I:$I, TRUE, All!$U:$U, $A2) | N2: =AVERAGEIFS(All!Y:Y, All!$G:$G, TRUE, All!$H:$H, TRUE, All!$I:$I, TRUE, All!$U:$U, $A2) | O2: =COUNTIFS(All!G:G,TRUE,All!$U:$U,$A2)/COUNTIF(All!$U2:$U34,Filter!$A2) | P2: =COUNTIFS(All!H:H,TRUE,All!$U:$U,$A2)/COUNTIF(All!$U2:$U34,Filter!$A2) | Q2: =COUNTIFS(All!I:I,TRUE,All!$U:$U,$A2)/COUNTIF(All!$U2:$U34,Filter!$A2)
A3: moderate | B3: =AVERAGEIFS(All!$J:$J, All!$G:$G, TRUE, All!$H:$H, TRUE, All!$I:$I, TRUE, All!$U:$U, A3) | C3: =AVERAGEIFS(All!K:K, All!$G:$G, TRUE, All!$H:$H, TRUE, All!$I:$I, TRUE, All!$U:$U, $A3) | D3: =AVERAGEIFS(All!L:L, All!$G:$G, TRUE, All!$H:$H, TRUE, All!$I:$I, TRUE, All!$U:$U, $A3) | E3: =AVERAGEIFS(All!M:M, All!$G:$G, TRUE, All!$H:$H, TRUE, All!$I:$I, TRUE, All!$U:$U, $A3) | F3: =AVERAGEIFS(All!N:N, All!$G:$G, TRUE, All!$H:$H, TRUE, All!$I:$I, TRUE, All!$U:$U, $A3) | G3: =AVERAGEIFS(All!O:O, All!$G:$G, TRUE, All!$H:$H, TRUE, All!$I:$I, TRUE, All!$U:$U, $A3) | H3: =AVERAGEIFS(All!P:P, All!$G:$G, TRUE, All!$H:$H, TRUE, All!$I:$I, TRUE, All!$U:$U, $A3) | I3: =AVERAGEIFS(All!Q:Q, All!$G:$G, TRUE, All!$H:$H, TRUE, All!$I:$I, TRUE, All!$U:$U, $A3) | J3: =AVERAGEIFS(All!R:R, All!$G:$G, TRUE, All!$H:$H, TRUE, All!$I:$I, TRUE, All!$U:$U, $A3) | K3: =AVERAGEIFS(All!V:V, All!$G:$G, TRUE, All!$H:$H, TRUE, All!$I:$I, TRUE, All!$U:$U, $A3) | L3: =AVERAGEIFS(All!W:W, All!$G:$G, TRUE, All!$H:$H, TRUE, All!$I:$I, TRUE, All!$U:$U, $A3) | M3: =AVERAGEIFS(All!X:X, All!$G:$G, TRUE, All!$H:$H, TRUE, All!$I:$I, TRUE, All!$U:$U, $A3) | N3: =AVERAGEIFS(All!Y:Y, All!$G:$G, TRUE, All!$H:$H, TRUE, All!$I:$I, TRUE, All!$U:$U, $A3) | O3: =COUNTIFS(All!G:G,TRUE,All!$U:$U,$A3)/COUNTIF(All!$U3:$U35,Filter!$A3) | P3: =COUNTIFS(All!H:H,TRUE,All!$U:$U,$A3)/COUNTIF(All!$U3:$U35,Filter!$A3) | Q3: =COUNTIFS(All!I:I,TRUE,All!$U:$U,$A3)/COUNTIF(All!$U3:$U35,Filter!$A3)
A4: complex | B4: =AVERAGEIFS(All!$J:$J, All!$G:$G, TRUE, All!$H:$H, TRUE, All!$I:$I, TRUE, All!$U:$U, A4) | C4: =AVERAGEIFS(All!K:K, All!$G:$G, TRUE, All!$H:$H, TRUE, All!$I:$I, TRUE, All!$U:$U, $A4) | D4: =AVERAGEIFS(All!L:L, All!$G:$G, TRUE, All!$H:$H, TRUE, All!$I:$I, TRUE, All!$U:$U, $A4) | E4: =AVERAGEIFS(All!M:M, All!$G:$G, TRUE, All!$H:$H, TRUE, All!$I:$I, TRUE, All!$U:$U, $A4) | F4: =AVERAGEIFS(All!N:N, All!$G:$G, TRUE, All!$H:$H, TRUE, All!$I:$I, TRUE, All!$U:$U, $A4) | G4: =AVERAGEIFS(All!O:O, All!$G:$G, TRUE, All!$H:$H, TRUE, All!$I:$I, TRUE, All!$U:$U, $A4) | H4: =AVERAGEIFS(All!P:P, All!$G:$G, TRUE, All!$H:$H, TRUE, All!$I:$I, TRUE, All!$U:$U, $A4) | I4: =AVERAGEIFS(All!Q:Q, All!$G:$G, TRUE, All!$H:$H, TRUE, All!$I:$I, TRUE, All!$U:$U, $A4) | J4: =AVERAGEIFS(All!R:R, All!$G:$G, TRUE, All!$H:$H, TRUE, All!$I:$I, TRUE, All!$U:$U, $A4) | K4: =AVERAGEIFS(All!V:V, All!$G:$G, TRUE, All!$H:$H, TRUE, All!$I:$I, TRUE, All!$U:$U, $A4) | L4: =AVERAGEIFS(All!W:W, All!$G:$G, TRUE, All!$H:$H, TRUE, All!$I:$I, TRUE, All!$U:$U, $A4) | M4: =AVERAGEIFS(All!X:X, All!$G:$G, TRUE, All!$H:$H, TRUE, All!$I:$I, TRUE, All!$U:$U, $A4) | N4: =AVERAGEIFS(All!Y:Y, All!$G:$G, TRUE, All!$H:$H, TRUE, All!$I:$I, TRUE, All!$U:$U, $A4) | O4: =COUNTIFS(All!G:G,TRUE,All!$U:$U,$A4)/COUNTIF(All!$U4:$U36,Filter!$A4) | P4: =COUNTIFS(All!H:H,TRUE,All!$U:$U,$A4)/COUNTIF(All!$U4:$U36,Filter!$A4) | Q4: =COUNTIFS(All!I:I,TRUE,All!$U:$U,$A4)/COUNTIF(All!$U4:$U36,Filter!$A4)

Sheet Overall
A1: difficulty | B1: rows | C1: vars | D1: latency_p50_ms | E1: latency_p95_ms | F1: latency_mean_ms | G1: lexical_query_overlap | H1: semantic_similarity_to_CQ | I1: semantic_soft_coverage_to_CQ | J1: tuple_cohesion | K1: determinism_score | L1: satisfiability_binding_score | M1: h1_overall | N1: semantic_diversity_score | O1: syntax_ok_rate | P1: satisfiable_rate | Q1: deterministic_rate
A2: ALL | B2: =AVERAGEIFS(All!J:J,All!$G:$G, TRUE,All!$H:$H, TRUE,All!$I:$I, TRUE) | C2: =AVERAGEIFS(All!K:K,All!$G:$G, TRUE,All!$H:$H, TRUE,All!$I:$I, TRUE) | D2: =AVERAGEIFS(All!L:L,All!$G:$G, TRUE,All!$H:$H, TRUE,All!$I:$I, TRUE) | E2: =AVERAGEIFS(All!M:M,All!$G:$G, TRUE,All!$H:$H, TRUE,All!$I:$I, TRUE) | F2: =AVERAGEIFS(All!N:N,All!$G:$G, TRUE,All!$H:$H, TRUE,All!$I:$I, TRUE) | G2: =AVERAGEIFS(All!O:O,All!$G:$G, TRUE,All!$H:$H, TRUE,All!$I:$I, TRUE) | H2: =AVERAGEIFS(All!P:P,All!$G:$G, TRUE,All!$H:$H, TRUE,All!$I:$I, TRUE) | I2: =AVERAGEIFS(All!Q:Q,All!$G:$G, TRUE,All!$H:$H, TRUE,All!$I:$I, TRUE) | J2: =AVERAGEIFS(All!R:R,All!$G:$G, TRUE,All!$H:$H, TRUE,All!$I:$I, TRUE) | K2: =AVERAGEIFS(All!V:V,All!$G:$G, TRUE,All!$H:$H, TRUE,All!$I:$I, TRUE) | L2: =AVERAGEIFS(All!W:W,All!$G:$G, TRUE,All!$H:$H, TRUE,All!$I:$I, TRUE) | M2: =AVERAGEIFS(All!X:X,All!$G:$G, TRUE,All!$H:$H, TRUE,All!$I:$I, TRUE) | N2: =AVERAGEIFS(All!Y:Y,All!$G:$G, TRUE,All!$H:$H, TRUE,All!$I:$I, TRUE) | O2: =COUNTIFS(All!G:G,TRUE)/COUNTA(All!$U2:$U34) | P2: =COUNTIFS(All!H:H,TRUE)/COUNTA(All!$U2:$U34) | Q2: =COUNTIFS(All!I:I,TRUE)/COUNTA(All!$U2:$U34)

Sheet All
A1: CQ | B1: Prompt | C1: gemma3:27b_Analysis_Result | D1: gemma3:27b_Analysis_Raw | E1: sparql_query | F1: eval_json | G1: syntax_ok | H1: satisfiable | I1: deterministic | J1: rows | K1: vars | L1: latency_p50_ms | M1: latency_p95_ms | N1: latency_mean_ms | O1: lexical_query_overlap | P1: semantic_similarity_to_CQ | Q1: semantic_soft_coverage_to_CQ | R1: tuple_cohesion | S1: always_unbound_vars | T1: variables | U1: difficulty | V1: determinism_score | W1: satisfiability_binding_score | X1: h1_overall | Y1: semantic_diversity_score
A2: Who are all the characters available? | B2: Task: Write a SPARQL query that answers the following competency question: Who are all the characters available? Requirements: - Use the schema to determine correct URIs and relationships. - Ensure the query retrieves the necessary information efficiently. - Provide only one full SPARQL query without placeholders. - Don't summarize or return an analysis of the given schema but return only the respective SPARQL query for the Competency Question. Context: Below is the TTL schema of the knowledge graph: @prefix dc: <http://purl.org/dc/elements/1.1/> . @prefix dcterms: <http://purl.org/dc/terms/> . @prefix foaf: <http://xmlns.com/foaf/0.1/> . @prefix ns1: <http://dbkwik.webdatacommons.org/marvel.wikia.com/property/> . @prefix ns2: <http://dbkwik.webdatacommons.org/ontology/> . @prefix ns3: <http://dbkwik.webdatacommons.org/marvel.wikia.com/property/%3> . @prefix ns7: <http://dbkwik.webdatacommons.org/marvel.wikia.com/property/alternate232%60> . @prefix owl: <http://www.w3.org/2002/07/owl#> . @prefix rdf: <http://www.w3.org/1999/02/22-rdf-syntax-ns#> . @prefix rdfs: <http://www.w3.org/2000/01/rdf-schema#> . @prefix skos: <http://www.w3.org/2004/02/skos/core#> . @prefix xsd: <http://www.w3.org/2001/XMLSchema#> . <http://dbkwik.webdatacommons.org/marvel.wikia.com/> a owl:Ontology . ns3:CdivAlign a rdf:Property ; rdfs:label "<div align"@en . ns1:a1ternate a rdf:Property ; rdfs:label "A1ternate"@en . ns1:after a rdf:Property ; rdfs:label "after"@en . ns1:align a rdf:Property ; rdfs:label "align"@en . ns1:alternate a rdf:Property ; rdfs:label "Alternate"@en . ns7: a rdf:Property ; rdfs:label "Alternate232`"@en . ns1:appearing a rdf:Property ; rdfs:label "Appearing"@en . ns1:background a rdf:Property ; rdfs:label "background"@en . ns1:baseofoperations a rdf:Property ; rdfs:label "BaseOfOperations"@en . ns1:before a rdf:Property ; rdfs:label "before"@en . ns1:body a rdf:Property ; rdfs:label "body"@en . ns1:border a rdf:Property ; rdfs:label "border"@en . ns1:box a rdf:Property ; rdfs:label "Box"@en . ns1:box1Image a rdf:Property ; rdfs:label "Box1 Image"@en . ns1:box1Text a rdf:Property ; rdfs:label "Box1 Text"@en . ns1:box2Image a rdf:Property ; rdfs:label "Box2 Image"@en . ns1:box2Text a rdf:Property ; rdfs:label "Box2 Text"@en . ns1:box3Image a rdf:Property ; rdfs:label "Box3 Image"@en . ns1:box3Text a rdf:Property ; rdfs:label "Box3 Text"@en . ns1:box4Image a rdf:Property ; rdfs:label "Box4 Image"@en . ns1:box4Text a rdf:Property ; rdfs:label "Box4 Text"@en . ns1:box5Image a rdf:Property ; rdfs:label "Box5 Image"@en . ns1:box5Text a rdf:Property ; rdfs:label "Box5 Text"@en . ns1:box6Image a rdf:Property ; rdfs:label "Box6 Image"@en . ns1:box6Text a rdf:Property ; rdfs:label "Box6 Text"@en . ns1:box7Image a rdf:Property ; rdfs:label "Box7 Image"@en . ns1:box7Text a rdf:Property ; rdfs:label "Box7 Text"@en . ns1:box8Image a rdf:Property ; rdfs:label "Box8 Image"@en . ns1:box8Text a rdf:Property ; rdfs:label "Box8 Text"@en . ns1:charref a rdf:Property ; rdfs:label "CharRef"@en . ns1:citizenship a rdf:Property ; rdfs:label "Citizenship"@en . ns1:colourist a rdf:Property ; rdfs:label "Colourist8 "@en . ns1:creators a rdf:Property ; rdfs:label "Creators"@en . ns1:crossovers a rdf:Property ; rdfs:label "Crossovers"@en . ns1:death a rdf:Property ; rdfs:label "Death"@en . ns1:description a rdf:Property ; rdfs:label "Description"@en . ns1:durability a rdf:Property ; rdfs:label "Durability"@en . ns1:editor a rdf:Property ; rdfs:label "Editor8 "@en . ns1:endmonth a rdf:Property ; rdfs:label "EndMonth"@en . ns1:endyear a rdf:Property ; rdfs:label "EndYear"@en . ns1:energyProjection a rdf:Property ; rdfs:label "Energy Projection"@en . ns1:equipment a rdf:Property ; rdfs:label "Equipment"@en . ns1:explanation a rdf:Property ; rdfs:label "Explanation"@en . ns1:externallinks a rdf:Property ; rdfs:label "externallinks"@en . ns1:eyes a rdf:Property ; rdfs:label "Eyes"@en . ns1:fandurability a rdf:Property ; rdfs:label "FanDurability"@en . ns1:fanenergyProjection a rdf:Property ; rdfs:label "FanEnergy Projection"@en . ns1:fanexplanation a rdf:Property ; rdfs:label "FanExplanation"@en . ns1:fanfightingSkills a rdf:Property ; rdfs:label "FanFighting Skills"@en . ns1:fanintelligence a rdf:Property ; rdfs:label "FanIntelligence"@en . ns1:fanreference a rdf:Property ; rdfs:label "FanReference"@en . ns1:fanspeed a rdf:Property ; rdfs:label "FanSpeed"@en . ns1:fanstrength a rdf:Property ; rdfs:label "FanStrength"@en . ns1:featured a rdf:Property ; rdfs:label "Featured"@en . ns1:fightingSkills a rdf:Property ; rdfs:label "Fighting Skills"@en . ns1:file a rdf:Property ; rdfs:label "File"@en . ns1:first a rdf:Property ; rdfs:label "First"@en . ns1:firstissue a rdf:Property ; rdfs:label "FirstIssue"@en . ns1:formattedtitle a rdf:Property ; rdfs:label "formattedtitle"@en . ns1:gender a rdf:Property ; rdfs:label "Gender"@en . ns1:group a rdf:Property ; rdfs:label "Group"@en . ns1:hair a rdf:Property ; rdfs:label "Hair"@en . ns1:historytext a rdf:Property ; rdfs:label "HistoryText"@en . ns1:id a rdf:Property ; rdfs:label "id"@en . ns1:identity a rdf:Property ; rdfs:label "Identity"@en . ns1:imageSize a rdf:Property ; rdfs:label "Image Size"@en . ns1:imagesize a rdf:Property ; rdfs:label "ImageSize"@en . ns1:inker a rdf:Property ; rdfs:label "Inker8 "@en . ns1:intelligence a rdf:Property ; rdfs:label "Intelligence"@en . ns1:issueimage a rdf:Property ; rdfs:label "IssueImage"@en . ns1:issuelist a rdf:Property ; rdfs:label "IssueList"@en . ns1:lastissue a rdf:Property ; rdfs:label "LastIssue"@en . ns1:letterer a rdf:Property ; rdfs:label "Letterer8 "@en . ns1:link a rdf:Property ; rdfs:label "link"@en . ns1:links a rdf:Property ; rdfs:label "Links"@en . ns1:linktext a rdf:Property ; rdfs:label "linktext"@en . ns1:logo a rdf:Property ; rdfs:label "Logo"@en . ns1:mainCharacter a rdf:Property ; rdfs:label "Main Character"@en . ns1:mainImageSize a rdf:Property ; rdfs:label "Main Image Size"@en . ns1:mainPicSize a rdf:Property ; rdfs:label "Main Pic Size"@en . ns1:mainimagesize a rdf:Property ; rdfs:label "MainImageSize"@en . ns1:message a rdf:Property ; rdfs:label "Message"@en . ns1:month a rdf:Property ; rdfs:label "Month"@en . ns1:movies a rdf:Property ; rdfs:label "Movies"@en . ns1:name a rdf:Property ; rdfs:label "name"@en . ns1:newHeader a rdf:Property ; rdfs:label "New Header1 "@en . ns1:newHeader1X a rdf:Property ; rdfs:label "New Header1 x"@en . ns1:next a rdf:Property ; rdfs:label "next"@en . ns1:nextissue a rdf:Property ; rdfs:label "NextIssue"@en . ns1:nextvol a rdf:Property ; rdfs:label "NextVol"@en . ns1:note a rdf:Property ; rdfs:label "note"@en . ns1:notes a rdf:Property ; rdfs:label "Notes"@en . ns1:origin a rdf:Property ; rdfs:label "Origin"@en . ns1:other a rdf:Property ; rdfs:label "Other"@en . ns1:others a rdf:Property ; rdfs:label "Others"@en . ns1:penciler a rdf:Property ; rdfs:label "Penciler8 "@en . ns1:placeofbirth a rdf:Property ; rdfs:label "PlaceOfBirth"@en . ns1:powers a rdf:Property ; rdfs:label "Powers"@en . ns1:previous a rdf:Property ; rdfs:label "previous"@en . ns1:previousissue a rdf:Property ; rdfs:label "PreviousIssue"@en . ns1:previousvol a rdf:Property ; rdfs:label "PreviousVol"@en . ns1:pthers a rdf:Property ; rdfs:label "Pthers"@en . ns1:publisher a rdf:Property ; rdfs:label "Publisher"@en . ns1:realname a rdf:Property ; rdfs:label "RealName"@en . ns1:realted a rdf:Property ; rdfs:label "Realted"@en . ns1:reference a rdf:Property ; rdfs:label "Reference"@en . ns1:references a rdf:Property ; rdfs:label "references"@en . ns1:related a rdf:Property ; rdfs:label "Related"@en . ns1:relatives a rdf:Property ; rdfs:label "Relatives"@en . ns1:releasedate a rdf:Property ; rdfs:label "ReleaseDate"@en . ns1:seeAlso a rdf:Property ; rdfs:label "See Also"@en . ns1:seealso a rdf:Property ; rdfs:label "SeeAlso"@en . ns1:solicit a rdf:Property ; rdfs:label "Solicit"@en . ns1:speed a rdf:Property ; rdfs:label "Speed"@en . ns1:startmonth a rdf:Property ; rdfs:label "StartMonth"@en . ns1:startyear a rdf:Property ; rdfs:label "StartYear"@en . ns1:story a rdf:Property ; rdfs:label "Story"@en . ns1:story1link a rdf:Property ; rdfs:label "Story1Link"@en . ns1:story3link a rdf:Property ; rdfs:label "Story3Link"@en . ns1:storyarcs a rdf:Property ; rdfs:label "StoryArcs"@en . ns1:storytitle a rdf:Property ; rdfs:label "StoryTitle"@en . ns1:strength a rdf:Property ; rdfs:label "Strength"@en . ns1:teames a rdf:Property ; rdfs:label "Teames"@en . ns1:teams a rdf:Property ; rdfs:label "Teams"@en . ns1:television a rdf:Property ; rdfs:label "Television"@en . ns1:title a rdf:Property ; rdfs:label "title"@en . ns1:titleImage a rdf:Property ; rdfs:label "Title Image"@en . ns1:totalissues a rdf:Property ; rdfs:label "TotalIssues"@en . ns1:trivia a rdf:Property ; rdfs:label "Trivia"@en . ns1:type a rdf:Property ; rdfs:label "Type"@en . ns1:universe a rdf:Property ; rdfs:label "Universe"@en . ns1:videoGame a rdf:Property ; rdfs:label "Video Game"@en . ns1:videoGames a rdf:Property ; rdfs:label "Video Games"@en . ns1:videogames a rdf:Property ; rdfs:label "VideoGames"@en . ns1:volumelogo a rdf:Property ; rdfs:label "VolumeLogo"@en . ns1:width a rdf:Property ; rdfs:label "width"@en . ns1:writer a rdf:Property ; rdfs:label "Writer8 "@en . ns1:year a rdf:Property ; rdfs:label "Year"@en . ns1:years a rdf:Property ; rdfs:label "years"@en . <http://dbkwik.webdatacommons.org/marvel.wikia.com/resource/$$_Maje$tic> a <http://dbkwik.webdatacommons.org/marvel.wikia.com/class/r> ; rdfs:label "$$ Maje$tic"^^rdf:langString ; ns2:thumbnail <http://marvel.wikia.com/wiki/Special:FilePath/$$_Maje$tic_from_Agents_of_Atlas_Vol_1_4_001.png?width=300> ; ns2:wikiPageWikiLink <http://dbkwik.webdatacommons.org/marvel.wikia.com/resource/Atlas_Foundation_(Earth-616)>, <http://dbkwik.webdatacommons.org/marvel.wikia.com/resource/Category:Boats_and_Subs> ; ns2:wikiPageWikiLinkText "''$$ Maje$tic''"^^rdf:langString ; dcterms:subject <http://dbkwik.webdatacommons.org/marvel.wikia.com/resource/Category:Boats_and_Subs> ; skos:altLabel "$$ Maje$tic"^^rdf:langString ; foaf:depiction <http://marvel.wikia.com/wiki/Special:FilePath/$$_Maje$tic_from_Agents_of_Atlas_Vol_1_4_001.png> . <http://dbkwik.webdatacommons.org/marvel.wikia.com/resource/$$_Maje$tic/Gallery> a owl:Thing ; rdfs:label "$$ Maje$tic/Gallery"^^rdf:langString ; ns2:thumbnail <http://marvel.wikia.com/wiki/Special:FilePath/$$_Maje$tic_from_Agents_of_Atlas_Vol_1_4_001.png?width=300> ; skos:altLabel "$$ Maje$tic/Gallery"^^rdf:langString ; foaf:depiction <http://marvel.wikia.com/wiki/Special:FilePath/$$_Maje$tic_from_Agents_of_Atlas_Vol_1_4_001.png> . <http://dbkwik.webdatacommons.org/marvel.wikia.com/resource/$_Cult_(Earth-616)/Gallery> a owl:Thing ; rdfs:label "$ Cult (Earth-616)/Gallery"^^rdf:langString ; ns2:thumbnail <http://marvel.wikia.com/wiki/Special:FilePath/$_Cult_(Earth-616)_from_Daredevil_Vol_1_242_0001.jpg?width=300> ; skos:altLabel "$ Cult (Earth-616)/Gallery"^^rdf:langString ; foaf:depiction <http://marvel.wikia.com/wiki/Special:FilePath/$_Cult_(Earth-616)_from_Daredevil_Vol_1_242_0001.jpg> . <http://dbkwik.webdatacommons.org/marvel.wikia.com/resource/%22Astral%22_Realm_of_Morgan_le_Fay> ns2:wikiPageWikiLinkText "\"Astral\" Realm of Morgan le Fay"^^rdf:langString . <http://dbkwik.webdatacommons.org/marvel.wikia.com/resource/%22Blondie%22_(Earth-9047)> ns2:wikiPageWikiLinkText "\"Blondie\""^^rdf:langString . <http://dbkwik.webdatacommons.org/marvel.wikia.com/resource/%22Spider-Girl%22_(Mutant/Spider_Clone)_(Earth-616)> a <http://dbkwik.webdatacommons.org/marvel.wikia.com/class/m> ; rdfs:label "\"Spider-Girl\" (Mutant/Spider Clone) (Earth-616)"^^rdf:langString ; ns2:thumbnail <http://marvel.wikia.com/wiki/Special:FilePath/Spider-Girl_(Mutant_Spider_Clone)_(Earth-616)_from_Avenging_Spider-Man_Vol_1_16_0001.png?width=300> ; ns2:wikiPageWikiLink <http://dbkwik.webdatacommons.org/marvel.wikia.com/resource/Anti-Spider_Squad_(Earth-616)> ; dcterms:subject <http://dbkwik.webdatacommons.org/marvel.wikia.com/resource/Category:Adhesive>, <http://dbkwik.webdatacommons.org/marvel.wikia.com/resource/Category:Arachnine_Form> . <http://dbkwik.webdatacommons.org/marvel.wikia.com/resource/%22Spider-Girl%22_(Mutant/Spider_Clone)_(Earth-616)/Gallery> a owl:Thing ; rdfs:label "\"Spider-Girl\" (Mutant/Spider Clone) (Earth-616)/Gallery"^^rdf:langString . <http://dbkwik.webdatacommons.org/marvel.wikia.com/resource/%27Bu_Tones> a owl:Thing ; rdfs:label "'Bu Tones"^^rdf:langString . <http://dbkwik.webdatacommons.org/marvel.wikia.com/resource/%27Lectron_(Earth-12772)> a <http://dbkwik.webdatacommons.org/marvel.wikia.com/class/m> ; rdfs:label "'Lectron (Earth-12772)"^^rdf:langString ; dcterms:subject <http://dbkwik.webdatacommons.org/marvel.wikia.com/resource/Category:Electrokinesis>, <http://dbkwik.webdatacommons.org/marvel.wikia.com/resource/Category:Flight> . <http://dbkwik.webdatacommons.org/marvel.wikia.com/resource/%27Lectron_(Earth-12772)/Gallery> a owl:Thing ; rdfs:label "'Lectron (Earth-12772)/Gallery"^^rdf:langString . <http://dbkwik.webdatacommons.org/marvel.wikia.com/resource/%27Maxwell_Stockbridge%27> a <http://dbkwik.webdatacommons.org/marvel.wikia.com/class/merge_to> ; rdfs:label "'Maxwell Stockbridge'"^^rdf:langString . <http://dbkwik.webdatacommons.org/marvel.wikia.com/resource/%27Nam_Magazine_Vol_1> a <http://dbkwik.webdatacommons.org/marvel.wikia.com/class/cisnodpl> ; rdfs:label "'Nam Magazine Vol 1"^^rdf:langString ; ns1:formattedtitle "'Nam Magazine #1"^^rdf:langString, "'Nam Magazine #10"^^rdf:langString, "'Nam Magazine #2"^^rdf:langString, "'Nam Magazine #3"^^rdf:langString, "'Nam Magazine #4"^^rdf:langString ; ns1:month "April"^^rdf:langString, "August"^^rdf:langString, "December"^^rdf:langString, "February"^^rdf:langString, "January"^^rdf:langString ; ns1:year 1988, 1989 . <http://dbkwik.webdatacommons.org/marvel.wikia.com/resource/%27Nam_Magazine_Vol_1_1> a <http://dbkwik.webdatacommons.org/marvel.wikia.com/class/a> ; rdfs:label "'Nam Magazine Vol 1 1"^^rdf:langString . <http://dbkwik.webdatacommons.org/marvel.wikia.com/resource/%27Nam_Magazine_Vol_1_10> a owl:Thing ; rdfs:label "'Nam Magazine Vol 1 10"^^rdf:langString . <http://dbkwik.webdatacommons.org/marvel.wikia.com/resource/%27Nam_Magazine_Vol_1_2> a owl:Thing ; rdfs:label "'Nam Magazine Vol 1 2"^^rdf:langString . <http://dbkwik.webdatacommons.org/marvel.wikia.com/resource/%27Nam_Magazine_Vol_1_3> a owl:Thing ; rdfs:label "'Nam Magazine Vol 1 3"^^rdf:langString . <http://dbkwik.webdatacommons.org/marvel.wikia.com/resource/%27Nam_Magazine_Vol_1_4> a owl:Thing ; rdfs:label "'Nam Magazine Vol 1 4"^^rdf:langString . <http://dbkwik.webdatacommons.org/marvel.wikia.com/resource/%27Nuff_Said> a <http://dbkwik.webdatacommons.org/marvel.wikia.com/class/c> ; rdfs:label "'Nuff Said"^^rdf:langString . <http://dbkwik.webdatacommons.org/marvel.wikia.com/resource/%27Selka_(Earth-928)> a <http://dbkwik.webdatacommons.org/marvel.wikia.com/class/r> ; rdfs:label "'Selka (Earth-928)"^^rdf:langString . <http://dbkwik.webdatacommons.org/marvel.wikia.com/resource/%27Spinner_(Earth-616)> a <http://dbkwik.webdatacommons.org/marvel.wikia.com/class/m> ; rdfs:label "'Spinner (Earth-616)"^^rdf:langString . <http://dbkwik.webdatacommons.org/marvel.wikia.com/resource/%27Vores_(Earth-616)> a <http://dbkwik.webdatacommons.org/marvel.wikia.com/class/r> ; rdfs:label "'Vores (Earth-616)"^^rdf:langString ; ns2:wikiPageExternalLink <http://www.marvunapp.com/Appendix/voresrjf.htm> . <http://dbkwik.webdatacommons.org/marvel.wikia.com/resource/...In_Chains!> a <http://dbkwik.webdatacommons.org/marvel.wikia.com/class/c> ; rdfs:label "...In Chains!"^^rdf:langString . <http://dbkwik.webdatacommons.org/marvel.wikia.com/resource/.675_side-slung_deflected_chamber_Van_Damme-Seagal_repeating_rifle> a <http://dbkwik.webdatacommons.org/marvel.wikia.com/class/r> ; rdfs:label ".675 side-slung deflected chamber Van Damme-Seagal repeating rifle"^^rdf:langString . <http://dbkwik.webdatacommons.org/marvel.wikia.com/resource/0-8-4_(Hydra_Weapon)> a <http://dbkwik.webdatacommons.org/marvel.wikia.com/class/r> ; rdfs:label "0-8-4 (Hydra Weapon)"^^rdf:langString . <http://dbkwik.webdatacommons.org/marvel.wikia.com/resource/100_Greatest_Marvels_of_All_Time_Vol_1> a <http://dbkwik.webdatacommons.org/marvel.wikia.com/class/cidnodpl> ; rdfs:label "100 Greatest Marvels of All Time Vol 1"^^rdf:langString ; ns1:storytitle "And Now... the Wolverine!"^^rdf:langString, "Days of Future Past"^^rdf:langString, "Powerless"^^rdf:langString, "Rubicon"^^rdf:langString ; ns1:year 2001 . <http://dbkwik.webdatacommons.org/marvel.wikia.com/resource/100_Greatest_Marvels_of_All_Time_Vol_1_1> a <http://dbkwik.webdatacommons.org/marvel.wikia.com/class/storygrab> ; rdfs:label "100 Greatest Marvels of All Time Vol 1 1"^^rdf:langString . <http://dbkwik.webdatacommons.org/marvel.wikia.com/resource/100_Greatest_Marvels_of_All_Time_Vol_1_10> a <http://dbkwik.webdatacommons.org/marvel.wikia.com/class/apn> ; rdfs:label "100 Greatest Marvels of All Time Vol 1 10"^^rdf:langString . <http://dbkwik.webdatacommons.org/marvel.wikia.com/resource/100_Greatest_Marvels_of_All_Time_Vol_1_2> a <http://dbkwik.webdatacommons.org/marvel.wikia.com/class/a> ; rdfs:label "100 Greatest Marvels of All Time Vol 1 2"^^rdf:langString . <http://dbkwik.webdatacommons.org/marvel.wikia.com/resource/100_Greatest_Marvels_of_All_Time_Vol_1_3> a <http://dbkwik.webdatacommons.org/marvel.wikia.com/class/a> ; rdfs:label "100 Greatest Marvels of All Time Vol 1 3"^^rdf:langString . <http://dbkwik.webdatacommons.org/marvel.wikia.com/resource/100_Greatest_Marvels_of_All_Time_Vol_1_4> a <http://dbkwik.webdatacommons.org/marvel.wikia.com/class/a> ; rdfs:label "100 Greatest Marvels of All Time Vol 1 4"^^rdf:langString . <http://dbkwik.webdatacommons.org/marvel.wikia.com/resource/100_Greatest_Marvels_of_All_Time_Vol_1_5> a <http://dbkwik.webdatacommons.org/marvel.wikia.com/class/a> ; rdfs:label "100 Greatest Marvels of All Time Vol 1 5"^^rdf:langString . <http://dbkwik.webdatacommons.org/marvel.wikia.com/resource/100th_Anniversary_Special_-_Avengers_Vol_1> a <http://dbkwik.webdatacommons.org/marvel.wikia.com/class/cis> ; rdfs:label "100th Anniversary Special - Avengers Vol 1"^^rdf:langString . <http://dbkwik.webdatacommons.org/marvel.wikia.com/resource/100th_Anniversary_Special_-_Fantastic_Four_Vol_1> a <http://dbkwik.webdatacommons.org/marvel.wikia.com/class/cis> ; rdfs:label "100th Anniversary Special - Fantastic Four Vol 1"^^rdf:langString . <http://dbkwik.webdatacommons.org/marvel.wikia.com/resource/100th_Anniversary_Special_-_Fantastic_Four_Vol_1_1> a <http://dbkwik.webdatacommons.org/marvel.wikia.com/class/flash> ; rdfs:label "100th Anniversary Special - Fantastic Four Vol 1 1"^^rdf:langString . <http://dbkwik.webdatacommons.org/marvel.wikia.com/resource/100th_Anniversary_Special_-_Guardians_of_the_Galaxy_Vol_1> a <http://dbkwik.webdatacommons.org/marvel.wikia.com/class/cis> ; rdfs:label "100th Anniversary Special - Guardians of the Galaxy Vol 1"^^rdf:langString . <http://dbkwik.webdatacommons.org/marvel.wikia.com/resource/100th_Anniversary_Special_-_Spider-Man_Vol_1> a <http://dbkwik.webdatacommons.org/marvel.wikia.com/class/cis> ; rdfs:label "100th Anniversary Special - Spider-Man Vol 1"^^rdf:langString . <http://dbkwik.webdatacommons.org/marvel.wikia.com/resource/100th_Anniversary_Special_-_X-Men_Vol_1> a <http://dbkwik.webdatacommons.org/marvel.wikia.com/class/cis> ; rdfs:label "100th Anniversary Special - X-Men Vol 1"^^rdf:langString . <http://dbkwik.webdatacommons.org/marvel.wikia.com/resource/100th_Anniversary_Special_-_X-Men_Vol_1_1> a <http://dbkwik.webdatacommons.org/marvel.wikia.com/class/cameo> ; rdfs:label "100th Anniversary Special - X-Men Vol 1 1"^^rdf:langString . <http://dbkwik.webdatacommons.org/marvel.wikia.com/resource/107_(Earth-616)> a <http://dbkwik.webdatacommons.org/marvel.wikia.com/class/m> ; rdfs:label "107 (Earth-616)"^^rdf:langString ; ns2:wikiPageExternalLink <http://www.marvunapp.com/Appendix3/psignsofthetimesjusticeastro.htm%23107> . <http://dbkwik.webdatacommons.org/marvel.wikia.com/resource/10th_century> rdfs:label "10th century"^^rdf:langString ; ns2:abstract """The following timeline describes the major events of Earth-616 in the 10th century of the Marvel Universe Timeline. """@en ; rdfs:comment """The following timeline describes the major events of Earth-616 in the 10th century of the Marvel Universe Timeline. """@en . <http://dbkwik.webdatacommons.org/marvel.wikia.com/resource/11-Ball_(Earth-616)> a <http://dbkwik.webdatacommons.org/marvel.wikia.com/class/m> ; rdfs:label "11-Ball (Earth-616)"^^rdf:langString ; ns2:wikiPageExternalLink <http://www.marvunapp.com/Appendix2/8ballsw.htm%23gang> . <http://dbkwik.webdatacommons.org/marvel.wikia.com/resource/11th_century> rdfs:label "11th century"^^rdf:langString ; ns2:abstract """The following timeline describes the major events of Earth-616 in the 11th century of the Marvel Universe Timeline. """@en ; rdfs:comment """The following timeline describes the major events of Earth-616 in the 11th century of the Marvel Universe Timeline. """@en . <http://dbkwik.webdatacommons.org/marvel.wikia.com/resource/12th_century> rdfs:label "12th century"^^rdf:langString ; ns2:abstract """The following timeline describes the major events of Earth-616 in the 12th century of the Marvel Universe Timeline. """@en ; rdfs:comment """The following timeline describes the major events of Earth-616 in the 12th century of the Marvel Universe Timeline. """@en . <http://dbkwik.webdatacommons.org/marvel.wikia.com/resource/13th_century> rdfs:label "13th century"^^rdf:langString ; ns2:abstract """The following timeline describes the major events of Earth-616 in the 13th century of the Marvel Universe Timeline. """@en ; rdfs:comment """The following timeline describes the major events of Earth-616 in the 13th century of the Marvel Universe Timeline. """@en . <http://dbkwik.webdatacommons.org/marvel.wikia.com/resource/14_(Earth-616)> rdfs:label "14 (Earth-616)"^^rdf:langString ; ns2:wikiPageExternalLink <http://www.marvunapp.com/Appendix3/psignsofthetimesjusticeastro.htm> . <http://dbkwik.webdatacommons.org/marvel.wikia.com/resource/14th_century> rdfs:label "14th century"^^rdf:langString ; ns2:abstract """The following timeline describes the major events of Earth-616 in the 14th century of the Marvel Universe Timeline. """@en ; rdfs:comment """The following timeline describes the major events of Earth-616 in the 14th century of the Marvel Universe Timeline. """@en . <http://dbkwik.webdatacommons.org/marvel.wikia.com/resource/15-Love_TPB_Vol_1> a <http://dbkwik.webdatacommons.org/marvel.wikia.com/class/cid> ; rdfs:label "15-Love TPB Vol 1"^^rdf:langString . <http://dbkwik.webdatacommons.org/marvel.wikia.com/resource/15-Love_TPB_Vol_1_1> a <http://dbkwik.webdatacommons.org/marvel.wikia.com/class/cid> ; rdfs:label "15-Love TPB Vol 1 1"^^rdf:langString . <http://dbkwik.webdatacommons.org/marvel.wikia.com/resource/15-Love_Vol_1> a <http://dbkwik.webdatacommons.org/marvel.wikia.com/class/cidnodpl> ; rdfs:label "15-Love Vol 1"^^rdf:langString ; ns1:releasedate "2011-03-08"^^xsd:date, "2011-08-06"^^xsd:date, 7 ; ns1:year 2011 . <http://dbkwik.webdatacommons.org/marvel.wikia.com/resource/15-Love_Vol_1_1> a <http://dbkwik.webdatacommons.org/marvel.wikia.com/class/only> ; rdfs:label "15-Love Vol 1 1"^^rdf:langString . <http://dbkwik.webdatacommons.org/marvel.wikia.com/resource/1602_Witch_Hunter_Angela_Vol_1_1> a <http://dbkwik.webdatacommons.org/marvel.wikia.com/class/1st> ; rdfs:label "1602 Witch Hunter Angela Vol 1 1"^^rdf:langString . <http://dbkwik.webdatacommons.org/marvel.wikia.com/resource/1602_Witch_Hunter_Angela_Vol_1_2> a <http://dbkwik.webdatacommons.org/marvel.wikia.com/class/flashonly> ; rdfs:label "1602 Witch Hunter Angela Vol 1 2"^^rdf:langString . <http://dbkwik.webdatacommons.org/marvel.wikia.com/resource/1602_Witch_Hunter_Angela_Vol_1_3> a <http://dbkwik.webdatacommons.org/marvel.wikia.com/class/mentioned> ; rdfs:label "1602 Witch Hunter Angela Vol 1 3"^^rdf:langString . <http://dbkwik.webdatacommons.org/marvel.wikia.com/resource/1602_Witch_Hunter_Angela_Vol_1_4> a <http://dbkwik.webdatacommons.org/marvel.wikia.com/class/1stas> ; rdfs:label "1602 Witch Hunter Angela Vol 1 4"^^rdf:langString . <http://dbkwik.webdatacommons.org/marvel.wikia.com/resource/1872_Vol_1_1> a <http://dbkwik.webdatacommons.org/marvel.wikia.com/class/minor> ; rdfs:label "1872 Vol 1 1"^^rdf:langString . <http://dbkwik.webdatacommons.org/marvel.wikia.com/resource/1872_Vol_1_2> a <http://dbkwik.webdatacommons.org/marvel.wikia.com/class/minor> ; rdfs:label "1872 Vol 1 2"^^rdf:langString . <http://dbkwik.webdatacommons.org/marvel.wikia.com/resource/1872_Vol_1_3> a <http://dbkwik.webdatacommons.org/marvel.wikia.com/class/minor> ; rdfs:label "1872 Vol 1 3"^^rdf:langString ; rdfs:comment "pt-br:1872 Vol 1 3"@en . <http://dbkwik.webdatacommons.org/marvel.wikia.com/resource/1872_Vol_1_4> a <http://dbkwik.webdatacommons.org/marvel.wikia.com/class/apn> ; rdfs:label "1872 Vol 1 4"^^rdf:langString . <http://dbkwik.webdatacommons.org/marvel.wikia.com/resource/18th_Kree_Diplomatic_Gestalt> a <http://dbkwik.webdatacommons.org/marvel.wikia.com/class/disambiguation> ; rdfs:label "18th Kree Diplomatic Gestalt"^^rdf:langString ; ns1:alternate <http://dbkwik.webdatacommons.org/marvel.wikia.com/resource/18th_Kree_Diplomatic_Gestalt_(Earth-TRN285)> ; ns2:wikiPageDisambiguates <http://dbkwik.webdatacommons.org/marvel.wikia.com/resource/18th_Kree_Diplomatic_Gestalt_(Earth-200080)>, <http://dbkwik.webdatacommons.org/marvel.wikia.com/resource/18th_Kree_Diplomatic_Gestalt_(Earth-TRN285)> . <http://dbkwik.webdatacommons.org/marvel.wikia.com/resource/1939_Daily_Bugle_Vol_1> a <http://dbkwik.webdatacommons.org/marvel.wikia.com/class/comic_list> ; rdfs:label "1939 Daily Bugle Vol 1"^^rdf:langString ; rdfs:comment "WtRedirect"@en . <http://dbkwik.webdatacommons.org/marvel.wikia.com/resource/198_(Earth-616)> a <http://dbkwik.webdatacommons.org/marvel.wikia.com/class/messagebox> ; rdfs:label "198 (Earth-616)"^^rdf:langString . <http://dbkwik.webdatacommons.org/marvel.wikia.com/resource/1st_Special_Forces_Operational_Detachment-Delta> a <http://dbkwik.webdatacommons.org/marvel.wikia.com/class/disambiguation> ; rdfs:label "1st Special Forces Operational Detachment-Delta"^^rdf:langString ; ns1:movies <http://dbkwik.webdatacommons.org/marvel.wikia.com/resource/1st_Special_Forces_Operational_Detachment-Delta_(Earth-TRN554)> ; ns2:wikiPageDisambiguates <http://dbkwik.webdatacommons.org/marvel.wikia.com/resource/1st_Special_Forces_Operational_Detachment-Delta_(Earth-616)>, <http://dbkwik.webdatacommons.org/marvel.wikia.com/resource/1st_Special_Forces_Operational_Detachment-Delta_(Earth-TRN554)> . <http://dbkwik.webdatacommons.org/marvel.wikia.com/resource/2-Gun_Western_Vol_1> a <http://dbkwik.webdatacommons.org/marvel.wikia.com/class/cidnodpl> ; rdfs:label "2-Gun Western Vol 1"^^rdf:langString ; ns1:year 1956 . <http://dbkwik.webdatacommons.org/marvel.wikia.com/resource/2001:_A_Space_Odyssey_Vol_1> a <http://dbkwik.webdatacommons.org/marvel.wikia.com/class/cidnodpl> ; rdfs:label "2001: A Space Odyssey Vol 1"^^rdf:langString . <http://dbkwik.webdatacommons.org/marvel.wikia.com/resource/2001:_A_Space_Odyssey_Vol_1_1> a <http://dbkwik.webdatacommons.org/marvel.wikia.com/class/only> ; rdfs:label "2001: A Space Odyssey Vol 1 1"^^rdf:langString . <http://dbkwik.webdatacommons.org/marvel.wikia.com/resource/2001:_A_Space_Odyssey_Vol_1_10> a <http://dbkwik.webdatacommons.org/marvel.wikia.com/class/apn> ; rdfs:label "2001: A Space Odyssey Vol 1 10"^^rdf:langString . <http://dbkwik.webdatacommons.org/marvel.wikia.com/resource/2001:_A_Space_Odyssey_Vol_1_7> a <http://dbkwik.webdatacommons.org/marvel.wikia.com/class/only> ; rdfs:label "2001: A Space Odyssey Vol 1 7"^^rdf:langString . <http://dbkwik.webdatacommons.org/marvel.wikia.com/resource/2001:_A_Space_Odyssey_Vol_1_8> a <http://dbkwik.webdatacommons.org/marvel.wikia.com/class/apn> ; rdfs:label "2001: A Space Odyssey Vol 1 8"^^rdf:langString . <http://dbkwik.webdatacommons.org/marvel.wikia.com/resource/2001_Comic_Books> a <http://dbkwik.webdatacommons.org/marvel.wikia.com/class/comicdisambig> ; rdfs:label "2001 Comic Books"^^rdf:langString ; rdfs:comment """See: for a complete list. __NOEDITSECTION__"""@en . <http://dbkwik.webdatacommons.org/marvel.wikia.com/resource/2010> a <http://dbkwik.webdatacommons.org/marvel.wikia.com/class/disambiguation> ; rdfs:label "2010"^^rdf:langString . <http://dbkwik.webdatacommons.org/marvel.wikia.com/resource/2010_Vol_1> a <http://dbkwik.webdatacommons.org/marvel.wikia.com/class/c> ; rdfs:label "2010 Vol 1"^^rdf:langString . <http://dbkwik.webdatacommons.org/marvel.wikia.com/resource/2018> a <http://dbkwik.webdatacommons.org/marvel.wikia.com/class/year_category> ; rdfs:label "2018"^^rdf:langString . <http://dbkwik.webdatacommons.org/marvel.wikia.com/resource/2019> a <http://dbkwik.webdatacommons.org/marvel.wikia.com/class/year_category> ; rdfs:label "2019"^^rdf:langString . <http://dbkwik.webdatacommons.org/marvel.wikia.com/resource/2099:_Manifest_Destiny_Vol_1_1> a <http://dbkwik.webdatacommons.org/marvel.wikia.com/class/apn> ; rdfs:label "2099: Manifest Destiny Vol 1 1"^^rdf:langString . <http://dbkwik.webdatacommons.org/marvel.wikia.com/resource/2099:_World_of_Tomorrow_Vol_1> a <http://dbkwik.webdatacommons.org/marvel.wikia.com/class/cisnodpl> ; rdfs:label "2099: World of Tomorrow Vol 1"^^rdf:langString . <http://dbkwik.webdatacommons.org/marvel.wikia.com/resource/2099_Limited_Ashcan_Vol_1> a <http://dbkwik.webdatacommons.org/marvel.wikia.com/class/cidnodpl> ; rdfs:label "2099 Limited Ashcan Vol 1"^^rdf:langString . <http://dbkwik.webdatacommons.org/marvel.wikia.com/resource/2099_Unlimited_Vol_1> a <http://dbkwik.webdatacommons.org/marvel.wikia.com/class/cisnodpl> ; rdfs:label "2099 Unlimited Vol 1"^^rdf:langString . <http://dbkwik.webdatacommons.org/marvel.wikia.com/resource/2099_Unlimited_Vol_1_1> a <http://dbkwik.webdatacommons.org/marvel.wikia.com/class/minor> ; rdfs:label "2099 Unlimited Vol 1 1"^^rdf:langString . <http://dbkwik.webdatacommons.org/marvel.wikia.com/resource/20th_century> a <http://dbkwik.webdatacommons.org/marvel.wikia.com/class/main> ; rdfs:label "20th century"^^rdf:langString ; rdfs:comment """The following timeline describes the major events of Earth-616 in the 20th. Only major fictional historical events are listed here. Please note that few exact dates have been given for these events, so approximations are used instead. Note also that a Sliding Timescale applies to Earth-616, so that events involving its inhabitants can only be determined as having happened a certain number of years before whatever the current date is. """@en . <http://dbkwik.webdatacommons.org/marvel.wikia.com/resource/23_Mill_Road> a <http://dbkwik.webdatacommons.org/marvel.wikia.com/class/c> ; rdfs:label "23 Mill Road"^^rdf:langString . <http://dbkwik.webdatacommons.org/marvel.wikia.com/resource/3-D_Man> a <http://dbkwik.webdatacommons.org/marvel.wikia.com/class/disambiguation> ; rdfs:label "3-D Man"^^rdf:langString ; ns1:description <http://dbkwik.webdatacommons.org/marvel.wikia.com/resource/Skrulls> ; ns1:logo 3 ; ns1:mainCharacter <http:/ | C2: This is a massive amount of data! You've provided a complex web of information including RDF triples, class definitions, and a huge number of related resources. This represents a detailed knowledge graph about Marvel Comics and its universe. Here's a breakdown of what this all means, along with some observations and potential uses: **Key Concepts & Data Types:** * **RDF Triples:** The foundation of this data. They take the form `subject - predicate - object`. For example: `http://dbkwik.webdatacommons.org/marvel.wikia.com/resource/Bruce_Banner_(Earth-616) - rdfs:label - "Bruce Banner (Earth-616)"`. This says that the resource "Bruce Banner (Earth-616)" has a label of "Bruce Banner (Earth-616)". * **Resources (Subjects & Objects):** These are the entities in your knowledge graph – characters, teams, events, concepts, etc. They are identified by URIs (Uniform Resource Identifiers), like `http://dbkwik.webdatacommons.org/marvel.wikia.com/resource/Bruce_Banner_(Earth-616)`. * **Predicates (Relationships):** These define the relationships between the resources. `rdfs:label`, `dcterms:subject`, `skos:related` are examples. * **Classes (OWL Classes):** These categorize resources. For example, `http://dbkwik.webdatacommons.org/marvel.wikia.com/class/character` defines a class for characters. * **Namespaces:** Prefixes like `rdfs:`, `skos:`, `dcterms:` are used to shorten URIs. For example, `rdfs:` refers to the Resource Description Framework Schema. **Observations:** * **Detailed Modeling:** You've modeled the Marvel universe with a high degree of granularity. There are classes for very specific types of things (e.g., `http://dbkwik.webdatacommons.org/marvel.wikia.com/class/storygrab`). * **Interconnectedness:** The RDF triples demonstrate how different entities are related. This is the power of a knowledge graph – you can traverse relationships to discover new information. * **Data Source:** The data appears to be derived from or related to DBpedia and the Marvel Wiki. * **Extensive Vocabulary:** You’ve used a wide range of vocabularies (RDF Schema, SKOS, Dublin Core, etc.) to describe the data. * **Schema.org Potential:** While not explicitly used, a lot of this could be mapped to Schema.org vocabulary for better interoperability with search engines. **Potential Uses:** * **Knowledge Graph Applications:** Build applications that can reason over the Marvel data. For example: * **Character Recommendations:** Suggest characters based on their relationships to others. * **Storyline Exploration:** Help users navigate complex storylines. * **"What If?" Scenarios:** Simulate different outcomes based on changes to the universe. * **Semantic Search:** Allow users to search for information using natural language queries. For example, "Find characters related to Iron Man." * **Data Integration:** Combine this data with other datasets (e.g., movie databases, comic book price guides). * **AI and Machine Learning:** Train AI models on this data to perform tasks like character recognition, storyline prediction, and sentiment analysis. * **Content Enrichment:** Add structured data to Marvel-related websites and applications to improve SEO and user experience. * **Data Visualization:** Create interactive visualizations of the Marvel universe to explore its relationships and connections. * **Chatbots & Virtual Assistants:** Build a chatbot that can answer questions about the Marvel universe. **Tools for Working with This Data:** * **SPARQL Endpoint:** A SPARQL endpoint allows you to query the knowledge graph using the SPARQL query language. You would need to load this data into a triplestore (see below) to use a SPARQL endpoint. * **Triplestores:** Triplestores are databases specifically designed to store and query RDF data. Popular options include: * Apache Jena Fuseki * GraphDB * Amazon Neptune * Stardog * **RDF Libraries:** Programming libraries that allow you to work with RDF data in your code. Examples include: * Apache Jena (Java) * RDFlib (Python) * rdflib-jsonld (Python - for working with JSON-LD) * **Graph Visualization Tools:** Tools to visually explore the connections in the knowledge graph. * Neo4j Bloom * Linkurious **Next Steps:** 1. **Load the Data:** Load this data into a triplestore. 2. **Query the Data:** Use SPARQL to query the data and explore the relationships between entities. 3. **Build an Application:** Choose a use case and start building an application that leverages the knowledge graph. This is a fantastic dataset! The level of detail and organization will allow you to build some truly powerful applications. Let me know if you have any specific questions about how to work with this data or if you'd like help with any of the next steps. | D2: model='gemma3:27b' created_at='2025-11-27T07:19:55.918007097Z' done=True done_reason='stop' total_duration=99449704313 load_duration=31400110213 prompt_eval_count=48616 prompt_eval_duration=37030713829 eval_count=1150 eval_duration=29637221937 message=Message(role='assistant', content='This is a massive amount of data! You\'ve provided a complex web of information including RDF triples, class definitions, and a huge number of related resources. This represents a detailed knowledge graph about Marvel Comics and its universe. Here\'s a breakdown of what this all means, along with some observations and potential uses:\n\n**Key Concepts & Data Types:**\n\n* **RDF Triples:** The foundation of this data. They take the form `subject - predicate - object`. For example: `http://dbkwik.webdatacommons.org/marvel.wikia.com/resource/Bruce_Banner_(Earth-616) - rdfs:label - "Bruce Banner (Earth-616)"`. This says that the resource "Bruce Banner (Earth-616)" has a label of "Bruce Banner (Earth-616)".\n* **Resources (Subjects & Objects):** These are the entities in your knowledge graph – characters, teams, events, concepts, etc. They are identified by URIs (Uniform Resource Identifiers), like `http://dbkwik.webdatacommons.org/marvel.wikia.com/resource/Bruce_Banner_(Earth-616)`.\n* **Predicates (Relationships):** These define the relationships between the resources. `rdfs:label`, `dcterms:subject`, `skos:related` are examples.\n* **Classes (OWL Classes):** These categorize resources. For example, `http://dbkwik.webdatacommons.org/marvel.wikia.com/class/character` defines a class for characters.\n* **Namespaces:** Prefixes like `rdfs:`, `skos:`, `dcterms:` are used to shorten URIs. For example, `rdfs:` refers to the Resource Description Framework Schema.\n\n**Observations:**\n\n* **Detailed Modeling:** You\'ve modeled the Marvel universe with a high degree of granularity. There are classes for very specific types of things (e.g., `http://dbkwik.webdatacommons.org/marvel.wikia.com/class/storygrab`).\n* **Interconnectedness:** The RDF triples demonstrate how different entities are related. This is the power of a knowledge graph – you can traverse relationships to discover new information.\n* **Data Source:** The data appears to be derived from or related to DBpedia and the Marvel Wiki.\n* **Extensive Vocabulary:** You’ve used a wide range of vocabularies (RDF Schema, SKOS, Dublin Core, etc.) to describe the data.\n* **Schema.org Potential:** While not explicitly used, a lot of this could be mapped to Schema.org vocabulary for better interoperability with search engines.\n\n**Potential Uses:**\n\n* **Knowledge Graph Applications:** Build applications that can reason over the Marvel data. For example:\n * **Character Recommendations:** Suggest characters based on their relationships to others.\n * **Storyline Exploration:** Help users navigate complex storylines.\n * **"What If?" Scenarios:** Simulate different outcomes based on changes to the universe.\n* **Semantic Search:** Allow users to search for information using natural language queries. For example, "Find characters related to Iron Man."\n* **Data Integration:** Combine this data with other datasets (e.g., movie databases, comic book price guides).\n* **AI and Machine Learning:** Train AI models on this data to perform tasks like character recognition, storyline prediction, and sentiment analysis.\n* **Content Enrichment:** Add structured data to Marvel-related websites and applications to improve SEO and user experience.\n* **Data Visualization:** Create interactive visualizations of the Marvel universe to explore its relationships and connections.\n* **Chatbots & Virtual Assistants:** Build a chatbot that can answer questions about the Marvel universe.\n\n**Tools for Working with This Data:**\n\n* **SPARQL Endpoint:** A SPARQL endpoint allows you to query the knowledge graph using the SPARQL query language. You would need to load this data into a triplestore (see below) to use a SPARQL endpoint.\n* **Triplestores:** Triplestores are databases specifically designed to store and query RDF data. Popular options include:\n * Apache Jena Fuseki\n * GraphDB\n * Amazon Neptune\n * Stardog\n* **RDF Libraries:** Programming libraries that allow you to work with RDF data in your code. Examples include:\n * Apache Jena (Java)\n * RDFlib (Python)\n * rdflib-jsonld (Python - for working with JSON-LD)\n* **Graph Visualization Tools:** Tools to visually explore the connections in the knowledge graph.\n * Neo4j Bloom\n * Linkurious\n\n**Next Steps:**\n\n1. **Load the Data:** Load this data into a triplestore.\n2. **Query the Data:** Use SPARQL to query the data and explore the relationships between entities.\n3. **Build an Application:** Choose a use case and start building an application that leverages the knowledge graph.\n\nThis is a fantastic dataset! The level of detail and organization will allow you to build some truly powerful applications. Let me know if you have any specific questions about how to work with this data or if you\'d like help with any of the next steps.\n', thinking=None, images=None, tool_calls=None) | E2: PREFIX dc: <http://purl.org/dc/elements/1.1/> PREFIX dcterms: <http://purl.org/dc/terms/> PREFIX foaf: <http://xmlns.com/foaf/0.1/> PREFIX ns1: <http://dbkwik.webdatacommons.org/marvel.wikia.com/property/> PREFIX ns2: <http://dbkwik.webdatacommons.org/ontology/> PREFIX ns3: <http://dbkwik.webdatacommons.org/marvel.wikia.com/property/%3> PREFIX ns7: <http://dbkwik.webdatacommons.org/marvel.wikia.com/property/alternate232%60> PREFIX owl: <http://www.w3.org/2002/07/owl#> PREFIX rdf: <http://www.w3.org/1999/02/22-rdf-syntax-ns#> PREFIX rdfs: <http://www.w3.org/2000/01/rdf-schema#> PREFIX skos: <http://www.w3.org/2004/02/skos/core#> PREFIX xsd: <http://www.w3.org/2001/XMLSchema#> Prefixes like `rdfs:`, `skos:`, `dcterms:` are used to shorten URIs. For example, `rdfs:` refers to the Resource Description Framework Schema. **Observations:** * **Detailed Modeling:** You've modeled the Marvel universe with a high degree of granularity. There are classes for very specific types of things (e.g., `http://dbkwik.webdatacommons.org/marvel.wikia.com/class/storygrab`). * **Interconnectedness:** The RDF triples demonstrate how different entities are related. This is the power of a knowledge graph – you can traverse relationships to discover new information. * **Data Source:** The data appears to be derived from or related to DBpedia and the Marvel Wiki. * **Extensive Vocabulary:** You’ve used a wide range of vocabularies (RDF Schema, SKOS, Dublin Core, etc.) to describe the data. * **Schema.org Potential:** While not explicitly used, a lot of this could be mapped to Schema.org vocabulary for better interoperability with search engines. **Potential Uses:** * **Knowledge Graph Applications:** Build applications that can reason over the Marvel data. For example: * **Character Recommendations:** Suggest characters based on their relationships to others. * **Storyline Exploration:** Help users navigate complex storylines. * **"What If?" Scenarios:** Simulate different outcomes based on changes to the universe. * **Semantic Search:** Allow users to search for information using natural language queries. For example, "Find characters related to Iron Man." * **Data Integration:** Combine this data with other datasets (e.g., movie databases, comic book price guides). * **AI and Machine Learning:** Train AI models on this data to perform tasks like character recognition, storyline prediction, and sentiment analysis. * **Content Enrichment:** Add structured data to Marvel-related websites and applications to improve SEO and user experience. * **Data Visualization:** Create interactive visualizations of the Marvel universe to explore its relationships and connections. * **Chatbots & Virtual Assistants:** Build a chatbot that can answer questions about the Marvel universe. **Tools for Working with This Data:** * **SPARQL Endpoint:** A SPARQL endpoint allows you to query the knowledge graph using the SPARQL query language. You would need to load this data into a triplestore (see below) to use a SPARQL endpoint. * **Triplestores:** Triplestores are databases specifically designed to store and query RDF data. Popular options include: * Apache Jena Fuseki * GraphDB * Amazon Neptune * Stardog * **RDF Libraries:** Programming libraries that allow you to work with RDF data in your code. Examples include: * Apache Jena (Java) * RDFlib (Python) * rdflib-jsonld (Python - for working with JSON-LD) * **Graph Visualization Tools:** Tools to visually explore the connections in the knowledge graph. * Neo4j Bloom * Linkurious **Next Steps:** 1. **Load the Data:** Load this data into a triplestore. 2. **Query the Data:** Use SPARQL to query the data and explore the relationships between entities. 3. **Build an Application:** Choose a use case and start building an application that leverages the knowledge graph. This is a fantastic dataset! The level of detail and organization will allow you to build some truly powerful applications. Let me know if you have any specific questions about how to work with this data or if you'd like help with any of the next steps. | F2: ERROR: QueryBadFormed: A bad request has been sent to the endpoint: probably the SPARQL query is badly formed. Response: b'Parse error: Lexical error at line 13, column 9. Encountered: \'32\' (32), after prefix "es"\n' | G2: FALSE | H2: FALSE | I2: FALSE | U2: simple | V2: 1 | W2: 1 | X2: 1 | Y2: 0.5
