Workbook

Sheet Screen
A1: KG | B1: Model | C1: Valid Syntax recognized | D1: Full Validity
A2: Big | B2: Claude | C2: =SUM(OFFSET('Screen with C'!$D$2, (ROW() - ROW($A$2)) * 3, 0, 3, 1)) -> 30 | D2: =SUM(OFFSET('Screen with C'!$E$2, (ROW() - ROW($A$2)) * 3, 0, 3, 1)) -> 26
B3: GPT5 | C3: =SUM(OFFSET('Screen with C'!$D$2, (ROW() - ROW($A$2)) * 3, 0, 3, 1)) -> 27 | D3: =SUM(OFFSET('Screen with C'!$E$2, (ROW() - ROW($A$2)) * 3, 0, 3, 1)) -> 26
B4: Deepseek R1 | C4: =SUM(OFFSET('Screen with C'!$D$2, (ROW() - ROW($A$2)) * 3, 0, 3, 1)) -> 6 | D4: =SUM(OFFSET('Screen with C'!$E$2, (ROW() - ROW($A$2)) * 3, 0, 3, 1)) -> 4
B5: GPT OSS | C5: =SUM(OFFSET('Screen with C'!$D$2, (ROW() - ROW($A$2)) * 3, 0, 3, 1)) -> 31 | D5: =SUM(OFFSET('Screen with C'!$E$2, (ROW() - ROW($A$2)) * 3, 0, 3, 1)) -> 25
B6: Granite 3.3 | C6: =SUM(OFFSET('Screen with C'!$D$2, (ROW() - ROW($A$2)) * 3, 0, 3, 1)) -> 14 | D6: =SUM(OFFSET('Screen with C'!$E$2, (ROW() - ROW($A$2)) * 3, 0, 3, 1)) -> 2
B7: Granite 4 | C7: =SUM(OFFSET('Screen with C'!$D$2, (ROW() - ROW($A$2)) * 3, 0, 3, 1)) -> 4 | D7: =SUM(OFFSET('Screen with C'!$E$2, (ROW() - ROW($A$2)) * 3, 0, 3, 1)) -> 0
B8: Llama 3.2 | C8: =SUM(OFFSET('Screen with C'!$D$2, (ROW() - ROW($A$2)) * 3, 0, 3, 1)) -> 5 | D8: =SUM(OFFSET('Screen with C'!$E$2, (ROW() - ROW($A$2)) * 3, 0, 3, 1)) -> 1
B9: Mistral Small 3.2 | C9: =SUM(OFFSET('Screen with C'!$D$2, (ROW() - ROW($A$2)) * 3, 0, 3, 1)) -> 19 | D9: =SUM(OFFSET('Screen with C'!$E$2, (ROW() - ROW($A$2)) * 3, 0, 3, 1)) -> 4
B10: Phi4 mini | C10: =SUM(OFFSET('Screen with C'!$D$2, (ROW() - ROW($A$2)) * 3, 0, 3, 1)) -> 1 | D10: =SUM(OFFSET('Screen with C'!$E$2, (ROW() - ROW($A$2)) * 3, 0, 3, 1)) -> 0
B11: Phi4 reasoning | C11: =SUM(OFFSET('Screen with C'!$D$2, (ROW() - ROW($A$2)) * 3, 0, 3, 1)) -> 1 | D11: =SUM(OFFSET('Screen with C'!$E$2, (ROW() - ROW($A$2)) * 3, 0, 3, 1)) -> 0
B12: Phi4 | C12: =SUM(OFFSET('Screen with C'!$D$2, (ROW() - ROW($A$2)) * 3, 0, 3, 1)) -> 0 | D12: =SUM(OFFSET('Screen with C'!$E$2, (ROW() - ROW($A$2)) * 3, 0, 3, 1)) -> 0
B13: Gemma3 | C13: =SUM(OFFSET('Screen with C'!$D$2, (ROW() - ROW($A$2)) * 3, 0, 3, 1)) -> 0 | D13: =SUM(OFFSET('Screen with C'!$E$2, (ROW() - ROW($A$2)) * 3, 0, 3, 1)) -> 0
A14: Small | B14: Claude | C14: =SUM(OFFSET('Screen with C'!$D$2, (ROW() - ROW($A$2)) * 3, 0, 3, 1)) -> 31 | D14: =SUM(OFFSET('Screen with C'!$E$2, (ROW() - ROW($A$2)) * 3, 0, 3, 1)) -> 26
B15: GPT5 | C15: =SUM(OFFSET('Screen with C'!$D$2, (ROW() - ROW($A$2)) * 3, 0, 3, 1)) -> 29 | D15: =SUM(OFFSET('Screen with C'!$E$2, (ROW() - ROW($A$2)) * 3, 0, 3, 1)) -> 29
B16: Deepseek R1 | C16: =SUM(OFFSET('Screen with C'!$D$2, (ROW() - ROW($A$2)) * 3, 0, 3, 1)) -> 14 | D16: =SUM(OFFSET('Screen with C'!$E$2, (ROW() - ROW($A$2)) * 3, 0, 3, 1)) -> 6
B17: GPT OSS | C17: =SUM(OFFSET('Screen with C'!$D$2, (ROW() - ROW($A$2)) * 3, 0, 3, 1)) -> 31 | D17: =SUM(OFFSET('Screen with C'!$E$2, (ROW() - ROW($A$2)) * 3, 0, 3, 1)) -> 24
B18: Granite 3.3 | C18: =SUM(OFFSET('Screen with C'!$D$2, (ROW() - ROW($A$2)) * 3, 0, 3, 1)) -> 0 | D18: =SUM(OFFSET('Screen with C'!$E$2, (ROW() - ROW($A$2)) * 3, 0, 3, 1)) -> 0
B19: Granite 4 | C19: =SUM(OFFSET('Screen with C'!$D$2, (ROW() - ROW($A$2)) * 3, 0, 3, 1)) -> 7 | D19: =SUM(OFFSET('Screen with C'!$E$2, (ROW() - ROW($A$2)) * 3, 0, 3, 1)) -> 1
B20: Llama 3.2 | C20: =SUM(OFFSET('Screen with C'!$D$2, (ROW() - ROW($A$2)) * 3, 0, 3, 1)) -> 8 | D20: =SUM(OFFSET('Screen with C'!$E$2, (ROW() - ROW($A$2)) * 3, 0, 3, 1)) -> 6
B21: Mistral Small 3.2 | C21: =SUM(OFFSET('Screen with C'!$D$2, (ROW() - ROW($A$2)) * 3, 0, 3, 1)) -> 16 | D21: =SUM(OFFSET('Screen with C'!$E$2, (ROW() - ROW($A$2)) * 3, 0, 3, 1)) -> 4
B22: Phi4 mini | C22: =SUM(OFFSET('Screen with C'!$D$2, (ROW() - ROW($A$2)) * 3, 0, 3, 1)) -> 5 | D22: =SUM(OFFSET('Screen with C'!$E$2, (ROW() - ROW($A$2)) * 3, 0, 3, 1)) -> 2
B23: Phi4 reasoning | C23: =SUM(OFFSET('Screen with C'!$D$2, (ROW() - ROW($A$2)) * 3, 0, 3, 1)) -> 0 | D23: =SUM(OFFSET('Screen with C'!$E$2, (ROW() - ROW($A$2)) * 3, 0, 3, 1)) -> 0
B24: Phi4 | C24: =SUM(OFFSET('Screen with C'!$D$2, (ROW() - ROW($A$2)) * 3, 0, 3, 1)) -> 0 | D24: =SUM(OFFSET('Screen with C'!$E$2, (ROW() - ROW($A$2)) * 3, 0, 3, 1)) -> 0
B25: Gemma3 | C25: =SUM(OFFSET('Screen with C'!$D$2, (ROW() - ROW($A$2)) * 3, 0, 3, 1)) -> 3 | D25: =SUM(OFFSET('Screen with C'!$E$2, (ROW() - ROW($A$2)) * 3, 0, 3, 1)) -> 0

Sheet Screen with C
A1: KG | B1: Model | C1: Complexity | D1: Valid Syntax recognized | E1: Full Validity
A2: Big | B2: Claude | C2: Simple | D2: 12 | E2: 11
C3: Moderate | D3: 10 | E3: 8
C4: Complex | D4: 8 | E4: 7
B5: GPT5 | C5: Simple | D5: 10 | E5: 10
C6: Moderate | D6: 9 | E6: 8
C7: Complex | D7: 8 | E7: 8
B8: Deepseek R1 | C8: Simple | D8: 3 | E8: 2
C9: Moderate | D9: 0 | E9: 0
C10: Complex | D10: 3 | E10: 2
B11: GPT OSS | C11: Simple | D11: 11 | E11: 7
C12: Moderate | D12: 10 | E12: 9
C13: Complex | D13: 10 | E13: 9
B14: Granite 3.3 | C14: Simple | D14: 5 | E14: 1
C15: Moderate | D15: 5 | E15: 0
C16: Complex | D16: 4 | E16: 1
B17: Granite4 | C17: Simple | D17: 2 | E17: 0
C18: Moderate | D18: 1 | E18: 0
C19: Complex | D19: 1 | E19: 0
B20: Llama 3.2 | C20: Simple | D20: 4 | E20: 1
C21: Moderate | D21: 0 | E21: 0
C22: Complex | D22: 1 | E22: 0
B23: Mistral Small 3.2 | C23: Simple | D23: 7 | E23: 4
C24: Moderate | D24: 6 | E24: 0
C25: Complex | D25: 6 | E25: 0
B26: Phi4 mini | C26: Simple | D26: 0 | E26: 0
C27: Moderate | D27: 1 | E27: 0
C28: Complex | D28: 0 | E28: 0
B29: Phi4 reasoning | C29: Simple | D29: 1 | E29: 0
C30: Moderate | D30: 0 | E30: 0
C31: Complex | D31: 0 | E31: 0
B32: Phi4 | C32: Simple | D32: 0 | E32: 0
C33: Moderate | D33: 0 | E33: 0
C34: Complex | D34: 0 | E34: 0
B35: Gemma3 | C35: Simple | D35: 0 | E35: 0
C36: Moderate | D36: 0 | E36: 0
C37: Complex | D37: 0 | E37: 0
A38: Small | B38: Claude | C38: Simple | D38: 12 | E38: 11
C39: Moderate | D39: 10 | E39: 8
C40: Complex | D40: 9 | E40: 7
...

Sheet H1-AM
A1: KG | B1: Model | C1: rows | D1: vars | E1: latency_p50_ms | F1: latency_p95_ms | G1: latency_mean_ms | H1: lexical_query_overlap | I1: semantic_similarity_to_CQ | J1: semantic_soft_coverage_to_CQ | K1: tuple_cohesion | L1: determinism_score | M1: satisfiability_binding_score | N1: h1_overall | O1: semantic_diversity_score | P1: syntax_ok_rate | Q1: satisfiable_rate | R1: deterministic_rate
A2: Big | B2: Claude | C2: 11628.192 | D2: 2.6538462 | E2: 2146.5712 | F2: 2293.5069 | G2: 2128.4808 | H2: 0.044615385 | I2: 0.70807692 | J2: 0.77038462 | K2: 0.88961538 | L2: 1 | M2: 0.93543956 | N2: 0.96771978 | O2: 0.35257631 | P2: 0.90909091 | Q2: 0.78787879 | R2: 0.90909091
B3: GPT5 | C3: 3629.3077 | D3: 4.2692308 | E3: 901.50115 | F3: 994.53846 | G3: 911.38 | H3: 0.040384615 | I3: 0.71269231 | J3: 0.77307692 | K3: 0.8736 | L3: 1 | M3: 0.84903846 | N3: 0.92451923 | O3: 0.34639316 | P3: 0.81818182 | Q3: 0.78787879 | R3: 0.81818182
B4: Deepseek R1 | C4: 495 | D4: 2.75 | E4: 660.84 | F4: 695.4075 | G4: 670.3425 | H4: 0.04 | I4: 0.7 | J4: 0.77 | K4: 0.9175 | L4: 1 | M4: 0.9375 | N4: 0.96875 | O4: 0.37784722 | P4: 0.18181818 | Q4: 0.12121212 | R4: 0.18181818
B5: GPT OSS | C5: 8120.08 | D5: 2.84 | E5: 281.552 | F5: 307.9592 | G5: 285.0212 | H5: 0.046 | I5: 0.7348 | J5: 0.7712 | K5: 0.91086957 | L5: 1 | M5: 0.77952381 | N5: 0.8897619 | O5: 0.30717937 | P5: 0.93939394 | Q5: 0.75757576 | R5: 0.93939394
B6: Granite 3.3 | C6: 18 | D6: 2 | E6: 15.22 | F6: 23.09 | G6: 16.345 | H6: 0.02 | I6: 0.665 | J6: 0.785 | K6: 0.92 | L6: 1 | M6: 0.33333333 | N6: 0.66666667 | O6: 0.29888889 | P6: 0.42424242 | Q6: 0.060606061 | R6: 0.42424242
B7: Granite 4 | C7: 0 | D7: 0 | E7: 0 | F7: 0 | G7: 0 | H7: 0 | I7: 0 | J7: 0 | K7: 0 | L7: 0 | M7: 0 | N7: 0 | O7: 0 | P7: 0.12121212 | Q7: 0 | R7: 0.12121212
B8: Llama 3.2 | C8: 186 | D8: 0 | E8: 13.67 | F8: 21.35 | G8: 16.17 | H8: 0.08 | I8: 0.6 | J8: 0.7 | K8: 0 | L8: 1 | M8: 1 | N8: 1 | O8: 0.5 | P8: 0.15151515 | Q8: 0.03030303 | R8: 0.15151515
B9: Mistral Small 3.2 | C9: 6298.75 | D9: 3 | E9: 10531.74 | F9: 10965.487 | G9: 10598.792 | H9: 0.0725 | I9: 0.71 | J9: 0.755 | K9: 0.955 | L9: 1 | M9: 0.75 | N9: 0.875 | O9: 0.19 | P9: 0.57575758 | Q9: 0.12121212 | R9: 0.57575758
B10: Phi4 mini | C10: 0 | D10: 0 | E10: 0 | F10: 0 | G10: 0 | H10: 0 | I10: 0 | J10: 0 | K10: 0 | L10: 0 | M10: 0 | N10: 0 | O10: 0 | P10: 0.03030303 | Q10: 0 | R10: 0.03030303
B11: Phi4 reasoning | C11: 0 | D11: 0 | E11: 0 | F11: 0 | G11: 0 | H11: 0 | I11: 0 | J11: 0 | K11: 0 | L11: 0 | M11: 0 | N11: 0 | O11: 0 | P11: 0.03030303 | Q11: 0 | R11: 0.03030303
B12: Phi4 | C12: 0 | D12: 0 | E12: 0 | F12: 0 | G12: 0 | H12: 0 | I12: 0 | J12: 0 | K12: 0 | L12: 0 | M12: 0 | N12: 0 | O12: 0 | P12: 0 | Q12: 0 | R12: 0
B13: Gemma3 | C13: 0 | D13: 0 | E13: 0 | F13: 0 | G13: 0 | H13: 0 | I13: 0 | J13: 0 | K13: 0 | L13: 0 | M13: 0 | N13: 0 | O13: 0 | P13: 0 | Q13: 0 | R13: 0
A14: Small | B14: Claude | C14: 5285.8462 | D14: 2.6538462 | E14: 1327.7115 | F14: 1353.4304 | G14: 1333.1004 | H14: 0.047307692 | I14: 0.69807692 | J14: 0.75615385 | K14: 0.74730769 | L14: 1 | M14: 0.93543956 | N14: 0.96771978 | O14: 0.55804182 | P14: 0.93939394 | Q14: 0.78787879 | R14: 0.93939394
B15: GPT5 | C15: 3670.8621 | D15: 4.2413793 | E15: 1728.9228 | F15: 1916.6383 | G15: 1784.201 | H15: 0.03862069 | I15: 0.70724138 | J15: 0.7562069 | K15: 0.74413793 | L15: 1 | M15: 0.90418719 | N15: 0.9520936 | O15: 0.55795384 | P15: 0.87878788 | Q15: 0.87878788 | R15: 0.87878788
B16: Deepseek R1 | C16: 1888.3333 | D16: 2.3333333 | E16: 72.951667 | F16: 76.72 | G16: 73.31 | H16: 0.056666667 | I16: 0.71333333 | J16: 0.76166667 | K16: 0.69833333 | L16: 1 | M16: 1 | N16: 1 | O16: 0.65157407 | P16: 0.42424242 | Q16: 0.18181818 | R16: 0.42424242
B17: GPT OSS | C17: 1569.75 | D17: 2.5 | E17: 336.82542 | F17: 343.20167 | G17: 336.43042 | H17: 0.065833333 | I17: 0.71708333 | J17: 0.77875 | K17: 0.74227273 | L17: 1 | M17: 0.82638889 | N17: 0.91319444 | O17: 0.57652778 | P17: 0.93939394 | Q17: 0.72727273 | R17: 0.93939394
B18: Granite 3.3 | C18: 0 | D18: 0 | E18: 0 | F18: 0 | G18: 0 | H18: 0 | I18: 0 | J18: 0 | K18: 0 | L18: 0 | M18: 0 | N18: 0 | O18: 0 | P18: 0 | Q18: 0 | R18: 0
B19: Granite 4 | C19: 18905 | D19: 1 | E19: 264.68 | F19: 275.25 | G19: 267.89 | H19: 0 | I19: 0.61 | J19: 0.65 | K19: 1 | L19: 1 | M19: 0 | N19: 0.5 | O19: 0.33333333 | P19: 0.21212121 | Q19: 0.03030303 | R19: 0.21212121
B20: Llama 3.2 | C20: 250609.67 | D20: 0.16666667 | E20: 6301.0217 | F20: 6549.51 | G20: 6354.775 | H20: 0.0066666667 | I20: 0.59166667 | J20: 0.68 | K20: 0.53 | L20: 1 | M20: 1 | N20: 1 | O20: 0.55388889 | P20: 0.24242424 | Q20: 0.18181818 | R20: 0.24242424
B21: Mistral Small 3.2 | C21: 1067.5 | D21: 0.75 | E21: 62.4475 | F21: 67.3125 | G21: 61.635 | H21: 0 | I21: 0.63 | J21: 0.7025 | K21: 0.595 | L21: 1 | M21: 1 | N21: 1 | O21: 0.62916667 | P21: 0.48484848 | Q21: 0.12121212 | R21: 0.48484848
B22: Phi4 mini | C22: 5.5 | D22: 1 | E22: 17.465 | F22: 17.715 | G22: 15.975 | H22: 0 | I22: 0.685 | J22: 0.72 | K22: 0.665 | L22: 1 | M22: 1 | N22: 1 | O22: 0.445 | P22: 0.15151515 | Q22: 0.060606061 | R22: 0.15151515
B23: Phi4 reasoning | C23: 0 | D23: 0 | E23: 0 | F23: 0 | G23: 0 | H23: 0 | I23: 0 | J23: 0 | K23: 0 | L23: 0 | M23: 0 | N23: 0 | O23: 0 | P23: 0 | Q23: 0 | R23: 0
B24: Phi4 | C24: 0 | D24: 0 | E24: 0 | F24: 0 | G24: 0 | H24: 0 | I24: 0 | J24: 0 | K24: 0 | L24: 0 | M24: 0 | N24: 0 | O24: 0 | P24: 0 | Q24: 0 | R24: 0
B25: Gemma3 | C25: 0 | D25: 0 | E25: 0 | F25: 0 | G25: 0 | H25: 0 | I25: 0 | J25: 0 | K25: 0 | L25: 0 | M25: 0 | N25: 0 | O25: 0 | P25: 0.090909091 | Q25: 0 | R25: 0.090909091

Sheet H1-AM&C
A1: KG | B1: Model | C1: Complexity | D1: rows | E1: vars | F1: latency_p50_ms | G1: latency_p95_ms | H1: latency_mean_ms | I1: lexical_query_overlap | J1: semantic_similarity_to_CQ | K1: semantic_soft_coverage_to_CQ | L1: tuple_cohesion | M1: determinism_score | N1: satisfiability_binding_score | O1: h1_overall | P1: semantic_diversity_score | Q1: syntax_ok_rate | R1: satisfiable_rate | S1: deterministic_rate
A2: Big | B2: Claude | C2: Simple | D2: 10956.364 | E2: 2.1818182 | F2: 3876.9082 | G2: 4024.6173 | H2: 3776.4345 | I2: 0.032727273 | J2: 0.70909091 | K2: 0.76727273 | L2: 0.88818182 | M2: 1 | N2: 1 | O2: 1 | P2: 0.29128788 | Q2: 1 | R2: 0.91666667 | S2: 1
C3: Moderate | D3: 21981 | E3: 2.25 | F3: 1343.0238 | G3: 1600.7088 | H3: 1419.0475 | I3: 0.07875 | J3: 0.69375 | K3: 0.77375 | L3: 0.865 | M3: 1 | N3: 0.96875 | O3: 0.984375 | P3: 0.43135417 | Q3: 0.90909091 | R3: 0.72727273 | S3: 0.90909091
C4: Complex | D4: 852.14286 | E4: 3.8571429 | F4: 345.81 | G4: 364.96 | H4: 349.62 | I4: 0.024285714 | J4: 0.72285714 | K4: 0.77142857 | L4: 0.92 | M4: 1 | N4: 0.79591837 | O4: 0.89795918 | P4: 0.35885488 | Q4: 0.8 | R4: 0.7 | S4: 0.8
B5: GPT5 | C5: Simple | D5: 200.8 | E5: 3.6 | F5: 86.626 | G5: 162.786 | H5: 109.748 | I5: 0.024 | J5: 0.707 | K5: 0.766 | L5: 0.909 | M5: 1 | N5: 0.91 | O5: 0.955 | P5: 0.22624444 | Q5: 0.83333333 | R5: 0.83333333 | S5: 0.83333333
C6: Moderate | D6: 6127.25 | E6: 3.875 | F6: 792.4725 | G6: 885.88625 | H6: 820.025 | I6: 0.0575 | J6: 0.7225 | K6: 0.775 | L6: 0.845 | M6: 1 | N6: 0.875 | O6: 0.9375 | P6: 0.46309028 | Q6: 0.81818182 | R6: 0.72727273 | S6: 0.81818182
C7: Complex | D7: 5417 | E7: 5.5 | F7: 2029.1238 | G7: 2142.8812 | H7: 2004.775 | I7: 0.04375 | J7: 0.71 | K7: 0.78 | L7: 0.85571429 | M7: 1 | N7: 0.746875 | O7: 0.8734375 | P7: 0.37988194 | Q7: 0.8 | R7: 0.8 | S7: 0.8
B8: Deepseek R1 | C8: Simple | D8: 179 | E8: 2 | F8: 1100.055 | G8: 1103.72 | H8: 1099.46 | I8: 0.08 | J8: 0.67 | K8: 0.785 | L8: 0.85 | M8: 1 | N8: 1 | O8: 1 | P8: 0.35583333 | Q8: 0.25 | R8: 0.16666667 | S8: 0.25
C9: Moderate | D9: 0 | E9: 0 | F9: 0 | G9: 0 | H9: 0 | I9: 0 | J9: 0 | K9: 0 | L9: 0 | M9: 0 | N9: 0 | O9: 0 | P9: 0 | Q9: 0 | R9: 0 | S9: 0
C10: Complex | D10: 811 | E10: 3.5 | F10: 221.625 | G10: 287.095 | H10: 241.225 | I10: 0 | J10: 0.73 | K10: 0.755 | L10: 0.985 | M10: 1 | N10: 0.875 | O10: 0.9375 | P10: 0.39986111 | Q10: 0.3 | R10: 0.2 | S10: 0.3
B11: GPT OSS | C11: Simple | D11: 759.85714 | E11: 1.8571429 | F11: 39.57 | G11: 41.504286 | H11: 39.744286 | I11: 0.022857143 | J11: 0.73714286 | K11: 0.77 | L11: 0.90142857 | M11: 1 | N11: 1 | O11: 1 | P11: 0.2552381 | Q11: 0.91666667 | R11: 0.58333333 | S11: 0.91666667
C12: Moderate | D12: 13126 | E12: 2.6666667 | F12: 348.39111 | G12: 404.83333 | H12: 364.63889 | I12: 0.071111111 | J12: 0.74222222 | K12: 0.77333333 | L12: 0.90777778 | M12: 1 | N12: 0.84259259 | O12: 0.9212963 | P12: 0.36435185 | Q12: 0.90909091 | R12: 0.81818182 | S12: 0.90909091
C13: Complex | D13: 8838.7778 | E13: 3.7777778 | F13: 402.92111 | G13: 418.32778 | H13: 396.17444 | I13: 0.038888889 | J13: 0.72555556 | K13: 0.77 | L13: 0.92428571 | M13: 1 | N13: 0.54497354 | O13: 0.77248677 | P13: 0.29040564 | Q13: 1 | R13: 0.9 | S13: 1
B14: Granite 3.3 | C14: Simple | D14: 1 | E14: 1 | F14: 9.31 | G14: 17.48 | H14: 11.88 | I14: 0 | J14: 0.68 | K14: 0.75 | L14: 1 | M14: 1 | N14: 0 | O14: 0.5 | P14: 0.33333333 | Q14: 0.41666667 | R14: 0.083333333 | S14: 0.41666667
C15: Moderate | D15: 0 | E15: 0 | F15: 0 | G15: 0 | H15: 0 | I15: 0 | J15: 0 | K15: 0 | L15: 0 | M15: 0 | N15: 0 | O15: 0 | P15: 0 | Q15: 0.45454545 | R15: 0 | S15: 0.45454545
C16: Complex | D16: 35 | E16: 3 | F16: 21.13 | G16: 28.7 | H16: 20.81 | I16: 0.04 | J16: 0.65 | K16: 0.82 | L16: 0.84 | M16: 1 | N16: 0.66666667 | O16: 0.83333333 | P16: 0.26444444 | Q16: 0.4 | R16: 0.1 | S16: 0.4
B17: Granite 4 | C17: Simple | D17: 0 | E17: 0 | F17: 0 | G17: 0 | H17: 0 | I17: 0 | J17: 0 | K17: 0 | L17: 0 | M17: 0 | N17: 0 | O17: 0 | P17: 0 | Q17: 0.16666667 | R17: 0 | S17: 0.16666667
C18: Moderate | D18: 0 | E18: 0 | F18: 0 | G18: 0 | H18: 0 | I18: 0 | J18: 0 | K18: 0 | L18: 0 | M18: 0 | N18: 0 | O18: 0 | P18: 0 | Q18: 0.090909091 | R18: 0 | S18: 0.090909091
C19: Complex | D19: 0 | E19: 0 | F19: 0 | G19: 0 | H19: 0 | I19: 0 | J19: 0 | K19: 0 | L19: 0 | M19: 0 | N19: 0 | O19: 0 | P19: 0 | Q19: 0.1 | R19: 0 | S19: 0.1
B20: Llama 3.2 | C20: Simple | D20: 186 | E20: 0 | F20: 13.67 | G20: 21.35 | H20: 16.17 | I20: 0.08 | J20: 0.6 | K20: 0.7 | L20: 0 | M20: 1 | N20: 1 | O20: 1 | P20: 0.5 | Q20: 0.33333333 | R20: 0.083333333 | S20: 0.33333333
C21: Moderate | D21: 0 | E21: 0 | F21: 0 | G21: 0 | H21: 0 | I21: 0 | J21: 0 | K21: 0 | L21: 0 | M21: 0 | N21: 0 | O21: 0 | P21: 0 | Q21: 0 | R21: 0 | S21: 0
C22: Complex | D22: 0 | E22: 0 | F22: 0 | G22: 0 | H22: 0 | I22: 0 | J22: 0 | K22: 0 | L22: 0 | M22: 0 | N22: 0 | O22: 0 | P22: 0 | Q22: 0.1 | R22: 0 | S22: 0.1
B23: Mistral Small 3.2 | C23: Simple | D23: 6298.75 | E23: 3 | F23: 10531.74 | G23: 10965.487 | H23: 10598.792 | I23: 0.0725 | J23: 0.71 | K23: 0.755 | L23: 0.955 | M23: 1 | N23: 0.75 | O23: 0.875 | P23: 0.19 | Q23: 0.58333333 | R23: 0.33333333 | S23: 0.58333333
C24: Moderate | D24: 0 | E24: 0 | F24: 0 | G24: 0 | H24: 0 | I24: 0 | J24: 0 | K24: 0 | L24: 0 | M24: 0 | N24: 0 | O24: 0 | P24: 0 | Q24: 0.54545455 | R24: 0 | S24: 0.54545455
C25: Complex | D25: 0 | E25: 0 | F25: 0 | G25: 0 | H25: 0 | I25: 0 | J25: 0 | K25: 0 | L25: 0 | M25: 0 | N25: 0 | O25: 0 | P25: 0 | Q25: 0.6 | R25: 0 | S25: 0.6
B26: Phi4 mini | C26: Simple | D26: 0 | E26: 0 | F26: 0 | G26: 0 | H26: 0 | I26: 0 | J26: 0 | K26: 0 | L26: 0 | M26: 0 | N26: 0 | O26: 0 | P26: 0 | Q26: 0 | R26: 0 | S26: 0
C27: Moderate | D27: 0 | E27: 0 | F27: 0 | G27: 0 | H27: 0 | I27: 0 | J27: 0 | K27: 0 | L27: 0 | M27: 0 | N27: 0 | O27: 0 | P27: 0 | Q27: 0.090909091 | R27: 0 | S27: 0.090909091
C28: Complex | D28: 0 | E28: 0 | F28: 0 | G28: 0 | H28: 0 | I28: 0 | J28: 0 | K28: 0 | L28: 0 | M28: 0 | N28: 0 | O28: 0 | P28: 0 | Q28: 0 | R28: 0 | S28: 0
B29: Phi4 reasoning | C29: Simple | D29: 0 | E29: 0 | F29: 0 | G29: 0 | H29: 0 | I29: 0 | J29: 0 | K29: 0 | L29: 0 | M29: 0 | N29: 0 | O29: 0 | P29: 0 | Q29: 0.083333333 | R29: 0 | S29: 0.083333333
C30: Moderate | D30: 0 | E30: 0 | F30: 0 | G30: 0 | H30: 0 | I30: 0 | J30: 0 | K30: 0 | L30: 0 | M30: 0 | N30: 0 | O30: 0 | P30: 0 | Q30: 0 | R30: 0 | S30: 0
C31: Complex | D31: 0 | E31: 0 | F31: 0 | G31: 0 | H31: 0 | I31: 0 | J31: 0 | K31: 0 | L31: 0 | M31: 0 | N31: 0 | O31: 0 | P31: 0 | Q31: 0 | R31: 0 | S31: 0
B32: Phi4 | C32: Simple | D32: 0 | E32: 0 | F32: 0 | G32: 0 | H32: 0 | I32: 0 | J32: 0 | K32: 0 | L32: 0 | M32: 0 | N32: 0 | O32: 0 | P32: 0 | Q32: 0 | R32: 0 | S32: 0
C33: Moderate | D33: 0 | E33: 0 | F33: 0 | G33: 0 | H33: 0 | I33: 0 | J33: 0 | K33: 0 | L33: 0 | M33: 0 | N33: 0 | O33: 0 | P33: 0 | Q33: 0 | R33: 0 | S33: 0
C34: Complex | D34: 0 | E34: 0 | F34: 0 | G34: 0 | H34: 0 | I34: 0 | J34: 0 | K34: 0 | L34: 0 | M34: 0 | N34: 0 | O34: 0 | P34: 0 | Q34: 0 | R34: 0 | S34: 0
B35: Gemma3 | C35: Simple | D35: 0 | E35: 0 | F35: 0 | G35: 0 | H35: 0 | I35: 0 | J35: 0 | K35: 0 | L35: 0 | M35: 0 | N35: 0 | O35: 0 | P35: 0 | Q35: 0 | R35: 0 | S35: 0
C36: Moderate | D36: 0 | E36: 0 | F36: 0 | G36: 0 | H36: 0 | I36: 0 | J36: 0 | K36: 0 | L36: 0 | M36: 0 | N36: 0 | O36: 0 | P36: 0 | Q36: 0 | R36: 0 | S36: 0
C37: Complex | D37: 0 | E37: 0 | F37: 0 | G37: 0 | H37: 0 | I37: 0 | J37: 0 | K37: 0 | L37: 0 | M37: 0 | N37: 0 | O37: 0 | P37: 0 | Q37: 0 | R37: 0 | S37: 0
A38: Small | B38: Claude | C38: Simple | D38: 1295.1818 | E38: 2.3636364 | F38: 64.166364 | G38: 66.057273 | H38: 63.701818 | I38: 0.030909091 | J38: 0.70272727 | K38: 0.74818182 | L38: 0.69909091 | M38: 1 | N38: 1 | O38: 1 | P38: 0.65060606 | Q38: 1 | R38: 0.91666667 | S38: 1
C39: Moderate | D39: 9907.25 | E39: 2.375 | F39: 1348.3363 | G39: 1357.9613 | H39: 1346.3275 | I39: 0.07875 | J39: 0.70875 | K39: 0.75625 | L39: 0.7425 | M39: 1 | N39: 0.96875 | O39: 0.984375 | P39: 0.49600694 | Q39: 0.90909091 | R39: 0.72727273 | S39: 0.90909091
C40: Complex | D40: 6275.2857 | E40: 3.4285714 | F40: 3289.7114 | G40: 3371.2671 | H40: 3312.7529 | I40: 0.037142857 | J40: 0.67857143 | K40: 0.76857143 | L40: 0.82857143 | M40: 1 | N40: 0.79591837 | O40: 0.89795918 | P40: 0.48348073 | Q40: 0.9 | R40: 0.7 | S40: 0.9
...

Sheet H2-AM
A1: KG | B1: Model | C1: rows | D1: vars | E1: latency_p50_ms | F1: latency_p95_ms | G1: latency_mean_ms | H1: lexical_query_overlap | I1: semantic_similarity_to_CQ | J1: semantic_soft_coverage_to_CQ | K1: tuple_cohesion | L1: determinism_score | M1: satisfiability_binding_score | N1: h1_overall | O1: semantic_diversity_score | P1: syntax_ok_rate | Q1: satisfiable_rate | R1: deterministic_rate
A2: Big | B2: Claude | C2: 11628.192 | D2: 2.6538462 | E2: 2146.5712 | F2: 2293.5069 | G2: 2128.4808 | H2: 0.044615385 | I2: 0.70807692 | J2: 0.77038462 | K2: 0.88961538 | L2: 1 | M2: 0.93543956 | N2: 0.96771978 | O2: 0.35257631 | P2: 0.90909091 | Q2: 0.78787879 | R2: 0.90909091
B3: GPT5 | C3: 3629.3077 | D3: 4.2692308 | E3: 901.50115 | F3: 994.53846 | G3: 911.38 | H3: 0.040384615 | I3: 0.71269231 | J3: 0.77307692 | K3: 0.8736 | L3: 1 | M3: 0.84903846 | N3: 0.92451923 | O3: 0.34639316 | P3: 0.81818182 | Q3: 0.78787879 | R3: 0.81818182
B4: Deepseek R1 | C4: 495 | D4: 2.75 | E4: 660.84 | F4: 695.4075 | G4: 670.3425 | H4: 0.04 | I4: 0.7 | J4: 0.77 | K4: 0.9175 | L4: 1 | M4: 0.9375 | N4: 0.96875 | O4: 0.37784722 | P4: 0.18181818 | Q4: 0.12121212 | R4: 0.18181818
B5: GPT OSS | C5: 8120.08 | D5: 2.84 | E5: 281.552 | F5: 307.9592 | G5: 285.0212 | H5: 0.046 | I5: 0.7348 | J5: 0.7712 | K5: 0.91086957 | L5: 1 | M5: 0.77952381 | N5: 0.8897619 | O5: 0.30717937 | P5: 0.93939394 | Q5: 0.75757576 | R5: 0.93939394
B6: Granite 3.3 | C6: 18 | D6: 2 | E6: 15.22 | F6: 23.09 | G6: 16.345 | H6: 0.02 | I6: 0.665 | J6: 0.785 | K6: 0.92 | L6: 1 | M6: 0.33333333 | N6: 0.66666667 | O6: 0.29888889 | P6: 0.42424242 | Q6: 0.060606061 | R6: 0.42424242
B7: Granite 4 | C7: 0 | D7: 0 | E7: 0 | F7: 0 | G7: 0 | H7: 0 | I7: 0 | J7: 0 | K7: 0 | L7: 0 | M7: 0 | N7: 0 | O7: 0 | P7: 0.12121212 | Q7: 0 | R7: 0.12121212
B8: Llama 3.2 | C8: 186 | D8: 0 | E8: 13.67 | F8: 21.35 | G8: 16.17 | H8: 0.08 | I8: 0.6 | J8: 0.7 | K8: 0 | L8: 1 | M8: 1 | N8: 1 | O8: 0.5 | P8: 0.15151515 | Q8: 0.03030303 | R8: 0.15151515
B9: Mistral Small 3.2 | C9: 6298.75 | D9: 3 | E9: 10531.74 | F9: 10965.487 | G9: 10598.792 | H9: 0.0725 | I9: 0.71 | J9: 0.755 | K9: 0.955 | L9: 1 | M9: 0.75 | N9: 0.875 | O9: 0.19 | P9: 0.57575758 | Q9: 0.12121212 | R9: 0.57575758
B10: Phi4 mini | C10: 0 | D10: 0 | E10: 0 | F10: 0 | G10: 0 | H10: 0 | I10: 0 | J10: 0 | K10: 0 | L10: 0 | M10: 0 | N10: 0 | O10: 0 | P10: 0.03030303 | Q10: 0 | R10: 0.03030303
B11: Phi4 reasoning | C11: 0 | D11: 0 | E11: 0 | F11: 0 | G11: 0 | H11: 0 | I11: 0 | J11: 0 | K11: 0 | L11: 0 | M11: 0 | N11: 0 | O11: 0 | P11: 0.03030303 | Q11: 0 | R11: 0.03030303
B12: Phi4 | C12: 0 | D12: 0 | E12: 0 | F12: 0 | G12: 0 | H12: 0 | I12: 0 | J12: 0 | K12: 0 | L12: 0 | M12: 0 | N12: 0 | O12: 0 | P12: 0 | Q12: 0 | R12: 0
B13: Gemma3 | C13: 0 | D13: 0 | E13: 0 | F13: 0 | G13: 0 | H13: 0 | I13: 0 | J13: 0 | K13: 0 | L13: 0 | M13: 0 | N13: 0 | O13: 0 | P13: 0 | Q13: 0 | R13: 0
A14: Small | B14: Claude | C14: 5285.8462 | D14: 2.6538462 | E14: 1327.7115 | F14: 1353.4304 | G14: 1333.1004 | H14: 0.047307692 | I14: 0.69807692 | J14: 0.75615385 | K14: 0.74730769 | L14: 1 | M14: 0.93543956 | N14: 0.96771978 | O14: 0.55804182 | P14: 0.93939394 | Q14: 0.78787879 | R14: 0.93939394
B15: GPT5 | C15: 3670.8621 | D15: 4.2413793 | E15: 1728.9228 | F15: 1916.6383 | G15: 1784.201 | H15: 0.03862069 | I15: 0.70724138 | J15: 0.7562069 | K15: 0.74413793 | L15: 1 | M15: 0.90418719 | N15: 0.9520936 | O15: 0.55795384 | P15: 0.87878788 | Q15: 0.87878788 | R15: 0.87878788
B16: Deepseek R1 | C16: 1888.3333 | D16: 2.3333333 | E16: 72.951667 | F16: 76.72 | G16: 73.31 | H16: 0.056666667 | I16: 0.71333333 | J16: 0.76166667 | K16: 0.69833333 | L16: 1 | M16: 1 | N16: 1 | O16: 0.65157407 | P16: 0.42424242 | Q16: 0.18181818 | R16: 0.42424242
B17: GPT OSS | C17: 1569.75 | D17: 2.5 | E17: 336.82542 | F17: 343.20167 | G17: 336.43042 | H17: 0.065833333 | I17: 0.71708333 | J17: 0.77875 | K17: 0.74227273 | L17: 1 | M17: 0.82638889 | N17: 0.91319444 | O17: 0.57652778 | P17: 0.93939394 | Q17: 0.72727273 | R17: 0.93939394
B18: Granite 3.3 | C18: 0 | D18: 0 | E18: 0 | F18: 0 | G18: 0 | H18: 0 | I18: 0 | J18: 0 | K18: 0 | L18: 0 | M18: 0 | N18: 0 | O18: 0 | P18: 0 | Q18: 0 | R18: 0
B19: Granite 4 | C19: 18905 | D19: 1 | E19: 264.68 | F19: 275.25 | G19: 267.89 | H19: 0 | I19: 0.61 | J19: 0.65 | K19: 1 | L19: 1 | M19: 0 | N19: 0.5 | O19: 0.33333333 | P19: 0.21212121 | Q19: 0.03030303 | R19: 0.21212121
B20: Llama 3.2 | C20: 250609.67 | D20: 0.16666667 | E20: 6301.0217 | F20: 6549.51 | G20: 6354.775 | H20: 0.0066666667 | I20: 0.59166667 | J20: 0.68 | K20: 0.53 | L20: 1 | M20: 1 | N20: 1 | O20: 0.55388889 | P20: 0.24242424 | Q20: 0.18181818 | R20: 0.24242424
B21: Mistral Small 3.2 | C21: 1067.5 | D21: 0.75 | E21: 62.4475 | F21: 67.3125 | G21: 61.635 | H21: 0 | I21: 0.63 | J21: 0.7025 | K21: 0.595 | L21: 1 | M21: 1 | N21: 1 | O21: 0.62916667 | P21: 0.48484848 | Q21: 0.12121212 | R21: 0.48484848
B22: Phi4 mini | C22: 5.5 | D22: 1 | E22: 17.465 | F22: 17.715 | G22: 15.975 | H22: 0 | I22: 0.685 | J22: 0.72 | K22: 0.665 | L22: 1 | M22: 1 | N22: 1 | O22: 0.445 | P22: 0.15151515 | Q22: 0.060606061 | R22: 0.15151515
B23: Phi4 reasoning | C23: 0 | D23: 0 | E23: 0 | F23: 0 | G23: 0 | H23: 0 | I23: 0 | J23: 0 | K23: 0 | L23: 0 | M23: 0 | N23: 0 | O23: 0 | P23: 0 | Q23: 0 | R23: 0
B24: Phi4 | C24: 0 | D24: 0 | E24: 0 | F24: 0 | G24: 0 | H24: 0 | I24: 0 | J24: 0 | K24: 0 | L24: 0 | M24: 0 | N24: 0 | O24: 0 | P24: 0 | Q24: 0 | R24: 0
B25: Gemma3 | C25: 0 | D25: 0 | E25: 0 | F25: 0 | G25: 0 | H25: 0 | I25: 0 | J25: 0 | K25: 0 | L25: 0 | M25: 0 | N25: 0 | O25: 0 | P25: 0 | Q25: 0 | R25: 0

Sheet H2-AM&C
A1: KG | B1: Model | C1: Complexity | D1: rows | E1: vars | F1: latency_p50_ms | G1: latency_p95_ms | H1: latency_mean_ms | I1: lexical_query_overlap | J1: semantic_similarity_to_CQ | K1: semantic_soft_coverage_to_CQ | L1: tuple_cohesion | M1: determinism_score | N1: satisfiability_binding_score | O1: h1_overall | P1: semantic_diversity_score | Q1: syntax_ok_rate | R1: satisfiable_rate | S1: deterministic_rate
A2: Big | B2: Claude | C2: Simple | D2: 10956.364 | E2: 2.1818182 | F2: 3876.9082 | G2: 4024.6173 | H2: 3776.4345 | I2: 0.032727273 | J2: 0.70909091 | K2: 0.76727273 | L2: 0.88818182 | M2: 1 | N2: 1 | O2: 1 | P2: 0.29128788 | Q2: 1 | R2: 0.91666667 | S2: 1
C3: Moderate | D3: 21981 | E3: 2.25 | F3: 1343.0238 | G3: 1600.7088 | H3: 1419.0475 | I3: 0.07875 | J3: 0.69375 | K3: 0.77375 | L3: 0.865 | M3: 1 | N3: 0.96875 | O3: 0.984375 | P3: 0.43135417 | Q3: 0.90909091 | R3: 0.72727273 | S3: 0.90909091
C4: Complex | D4: 852.14286 | E4: 3.8571429 | F4: 345.81 | G4: 364.96 | H4: 349.62 | I4: 0.024285714 | J4: 0.72285714 | K4: 0.77142857 | L4: 0.92 | M4: 1 | N4: 0.79591837 | O4: 0.89795918 | P4: 0.35885488 | Q4: 0.8 | R4: 0.7 | S4: 0.8
B5: GPT5 | C5: Simple | D5: 200.8 | E5: 3.6 | F5: 86.626 | G5: 162.786 | H5: 109.748 | I5: 0.024 | J5: 0.707 | K5: 0.766 | L5: 0.909 | M5: 1 | N5: 0.91 | O5: 0.955 | P5: 0.22624444 | Q5: 0.83333333 | R5: 0.83333333 | S5: 0.83333333
C6: Moderate | D6: 6127.25 | E6: 3.875 | F6: 792.4725 | G6: 885.88625 | H6: 820.025 | I6: 0.0575 | J6: 0.7225 | K6: 0.775 | L6: 0.845 | M6: 1 | N6: 0.875 | O6: 0.9375 | P6: 0.46309028 | Q6: 0.81818182 | R6: 0.72727273 | S6: 0.81818182
C7: Complex | D7: 5417 | E7: 5.5 | F7: 2029.1238 | G7: 2142.8812 | H7: 2004.775 | I7: 0.04375 | J7: 0.71 | K7: 0.78 | L7: 0.85571429 | M7: 1 | N7: 0.746875 | O7: 0.8734375 | P7: 0.37988194 | Q7: 0.8 | R7: 0.8 | S7: 0.8
B8: Deepseek R1 | C8: Simple | D8: 179 | E8: 2 | F8: 1100.055 | G8: 1103.72 | H8: 1099.46 | I8: 0.08 | J8: 0.67 | K8: 0.785 | L8: 0.85 | M8: 1 | N8: 1 | O8: 1 | P8: 0.35583333 | Q8: 0.25 | R8: 0.16666667 | S8: 0.25
C9: Moderate | D9: 0 | E9: 0 | F9: 0 | G9: 0 | H9: 0 | I9: 0 | J9: 0 | K9: 0 | L9: 0 | M9: 0 | N9: 0 | O9: 0 | P9: 0 | Q9: 0 | R9: 0 | S9: 0
C10: Complex | D10: 811 | E10: 3.5 | F10: 221.625 | G10: 287.095 | H10: 241.225 | I10: 0 | J10: 0.73 | K10: 0.755 | L10: 0.985 | M10: 1 | N10: 0.875 | O10: 0.9375 | P10: 0.39986111 | Q10: 0.3 | R10: 0.2 | S10: 0.3
B11: GPT OSS | C11: Simple | D11: 759.85714 | E11: 1.8571429 | F11: 39.57 | G11: 41.504286 | H11: 39.744286 | I11: 0.022857143 | J11: 0.73714286 | K11: 0.77 | L11: 0.90142857 | M11: 1 | N11: 1 | O11: 1 | P11: 0.2552381 | Q11: 0.91666667 | R11: 0.58333333 | S11: 0.91666667
C12: Moderate | D12: 13126 | E12: 2.6666667 | F12: 348.39111 | G12: 404.83333 | H12: 364.63889 | I12: 0.071111111 | J12: 0.74222222 | K12: 0.77333333 | L12: 0.90777778 | M12: 1 | N12: 0.84259259 | O12: 0.9212963 | P12: 0.36435185 | Q12: 0.90909091 | R12: 0.81818182 | S12: 0.90909091
C13: Complex | D13: 8838.7778 | E13: 3.7777778 | F13: 402.92111 | G13: 418.32778 | H13: 396.17444 | I13: 0.038888889 | J13: 0.72555556 | K13: 0.77 | L13: 0.92428571 | M13: 1 | N13: 0.54497354 | O13: 0.77248677 | P13: 0.29040564 | Q13: 1 | R13: 0.9 | S13: 1
B14: Granite 3.3 | C14: Simple | D14: 1 | E14: 1 | F14: 9.31 | G14: 17.48 | H14: 11.88 | I14: 0 | J14: 0.68 | K14: 0.75 | L14: 1 | M14: 1 | N14: 0 | O14: 0.5 | P14: 0.33333333 | Q14: 0.41666667 | R14: 0.083333333 | S14: 0.41666667
C15: Moderate | D15: 0 | E15: 0 | F15: 0 | G15: 0 | H15: 0 | I15: 0 | J15: 0 | K15: 0 | L15: 0 | M15: 0 | N15: 0 | O15: 0 | P15: 0 | Q15: 0.45454545 | R15: 0 | S15: 0.45454545
C16: Complex | D16: 35 | E16: 3 | F16: 21.13 | G16: 28.7 | H16: 20.81 | I16: 0.04 | J16: 0.65 | K16: 0.82 | L16: 0.84 | M16: 1 | N16: 0.66666667 | O16: 0.83333333 | P16: 0.26444444 | Q16: 0.4 | R16: 0.1 | S16: 0.4
B17: Granite 4 | C17: Simple | D17: 0 | E17: 0 | F17: 0 | G17: 0 | H17: 0 | I17: 0 | J17: 0 | K17: 0 | L17: 0 | M17: 0 | N17: 0 | O17: 0 | P17: 0 | Q17: 0.16666667 | R17: 0 | S17: 0.16666667
C18: Moderate | D18: 0 | E18: 0 | F18: 0 | G18: 0 | H18: 0 | I18: 0 | J18: 0 | K18: 0 | L18: 0 | M18: 0 | N18: 0 | O18: 0 | P18: 0 | Q18: 0.090909091 | R18: 0 | S18: 0.090909091
C19: Complex | D19: 0 | E19: 0 | F19: 0 | G19: 0 | H19: 0 | I19: 0 | J19: 0 | K19: 0 | L19: 0 | M19: 0 | N19: 0 | O19: 0 | P19: 0 | Q19: 0.1 | R19: 0 | S19: 0.1
B20: Llama 3.2 | C20: Simple | D20: 186 | E20: 0 | F20: 13.67 | G20: 21.35 | H20: 16.17 | I20: 0.08 | J20: 0.6 | K20: 0.7 | L20: 0 | M20: 1 | N20: 1 | O20: 1 | P20: 0.5 | Q20: 0.33333333 | R20: 0.083333333 | S20: 0.33333333
C21: Moderate | D21: 0 | E21: 0 | F21: 0 | G21: 0 | H21: 0 | I21: 0 | J21: 0 | K21: 0 | L21: 0 | M21: 0 | N21: 0 | O21: 0 | P21: 0 | Q21: 0 | R21: 0 | S21: 0
C22: Complex | D22: 0 | E22: 0 | F22: 0 | G22: 0 | H22: 0 | I22: 0 | J22: 0 | K22: 0 | L22: 0 | M22: 0 | N22: 0 | O22: 0 | P22: 0 | Q22: 0.1 | R22: 0 | S22: 0.1
B23: Mistral Small 3.2 | C23: Simple | D23: 6298.75 | E23: 3 | F23: 10531.74 | G23: 10965.487 | H23: 10598.792 | I23: 0.0725 | J23: 0.71 | K23: 0.755 | L23: 0.955 | M23: 1 | N23: 0.75 | O23: 0.875 | P23: 0.19 | Q23: 0.58333333 | R23: 0.33333333 | S23: 0.58333333
C24: Moderate | D24: 0 | E24: 0 | F24: 0 | G24: 0 | H24: 0 | I24: 0 | J24: 0 | K24: 0 | L24: 0 | M24: 0 | N24: 0 | O24: 0 | P24: 0 | Q24: 0.54545455 | R24: 0 | S24: 0.54545455
C25: Complex | D25: 0 | E25: 0 | F25: 0 | G25: 0 | H25: 0 | I25: 0 | J25: 0 | K25: 0 | L25: 0 | M25: 0 | N25: 0 | O25: 0 | P25: 0 | Q25: 0.6 | R25: 0 | S25: 0.6
B26: Phi4 mini | C26: Simple | D26: 0 | E26: 0 | F26: 0 | G26: 0 | H26: 0 | I26: 0 | J26: 0 | K26: 0 | L26: 0 | M26: 0 | N26: 0 | O26: 0 | P26: 0 | Q26: 0 | R26: 0 | S26: 0
C27: Moderate | D27: 0 | E27: 0 | F27: 0 | G27: 0 | H27: 0 | I27: 0 | J27: 0 | K27: 0 | L27: 0 | M27: 0 | N27: 0 | O27: 0 | P27: 0 | Q27: 0.090909091 | R27: 0 | S27: 0.090909091
C28: Complex | D28: 0 | E28: 0 | F28: 0 | G28: 0 | H28: 0 | I28: 0 | J28: 0 | K28: 0 | L28: 0 | M28: 0 | N28: 0 | O28: 0 | P28: 0 | Q28: 0 | R28: 0 | S28: 0
B29: Phi4 reasoning | C29: Simple | D29: 0 | E29: 0 | F29: 0 | G29: 0 | H29: 0 | I29: 0 | J29: 0 | K29: 0 | L29: 0 | M29: 0 | N29: 0 | O29: 0 | P29: 0 | Q29: 0.083333333 | R29: 0 | S29: 0.083333333
C30: Moderate | D30: 0 | E30: 0 | F30: 0 | G30: 0 | H30: 0 | I30: 0 | J30: 0 | K30: 0 | L30: 0 | M30: 0 | N30: 0 | O30: 0 | P30: 0 | Q30: 0 | R30: 0 | S30: 0
C31: Complex | D31: 0 | E31: 0 | F31: 0 | G31: 0 | H31: 0 | I31: 0 | J31: 0 | K31: 0 | L31: 0 | M31: 0 | N31: 0 | O31: 0 | P31: 0 | Q31: 0 | R31: 0 | S31: 0
B32: Phi4 | C32: Simple | D32: 0 | E32: 0 | F32: 0 | G32: 0 | H32: 0 | I32: 0 | J32: 0 | K32: 0 | L32: 0 | M32: 0 | N32: 0 | O32: 0 | P32: 0 | Q32: 0 | R32: 0 | S32: 0
C33: Moderate | D33: 0 | E33: 0 | F33: 0 | G33: 0 | H33: 0 | I33: 0 | J33: 0 | K33: 0 | L33: 0 | M33: 0 | N33: 0 | O33: 0 | P33: 0 | Q33: 0 | R33: 0 | S33: 0
C34: Complex | D34: 0 | E34: 0 | F34: 0 | G34: 0 | H34: 0 | I34: 0 | J34: 0 | K34: 0 | L34: 0 | M34: 0 | N34: 0 | O34: 0 | P34: 0 | Q34: 0 | R34: 0 | S34: 0
B35: Gemma3 | C35: Simple | D35: 0 | E35: 0 | F35: 0 | G35: 0 | H35: 0 | I35: 0 | J35: 0 | K35: 0 | L35: 0 | M35: 0 | N35: 0 | O35: 0 | P35: 0 | Q35: 0 | R35: 0 | S35: 0
C36: Moderate | D36: 0 | E36: 0 | F36: 0 | G36: 0 | H36: 0 | I36: 0 | J36: 0 | K36: 0 | L36: 0 | M36: 0 | N36: 0 | O36: 0 | P36: 0 | Q36: 0 | R36: 0 | S36: 0
C37: Complex | D37: 0 | E37: 0 | F37: 0 | G37: 0 | H37: 0 | I37: 0 | J37: 0 | K37: 0 | L37: 0 | M37: 0 | N37: 0 | O37: 0 | P37: 0 | Q37: 0 | R37: 0 | S37: 0
A38: Small | B38: Claude | C38: Simple | D38: 1295.1818 | E38: 2.3636364 | F38: 64.166364 | G38: 66.057273 | H38: 63.701818 | I38: 0.030909091 | J38: 0.70272727 | K38: 0.74818182 | L38: 0.69909091 | M38: 1 | N38: 1 | O38: 1 | P38: 0.65060606 | Q38: 1 | R38: 0.91666667 | S38: 1
C39: Moderate | D39: 9907.25 | E39: 2.375 | F39: 1348.3363 | G39: 1357.9613 | H39: 1346.3275 | I39: 0.07875 | J39: 0.70875 | K39: 0.75625 | L39: 0.7425 | M39: 1 | N39: 0.96875 | O39: 0.984375 | P39: 0.49600694 | Q39: 0.90909091 | R39: 0.72727273 | S39: 0.90909091
C40: Complex | D40: 6275.2857 | E40: 3.4285714 | F40: 3289.7114 | G40: 3371.2671 | H40: 3312.7529 | I40: 0.037142857 | J40: 0.67857143 | K40: 0.76857143 | L40: 0.82857143 | M40: 1 | N40: 0.79591837 | O40: 0.89795918 | P40: 0.48348073 | Q40: 0.9 | R40: 0.7 | S40: 0.9
...
